Workbook

Sheet الشمالي
A1: المحطة | B1: المحول | C1: الجهد | D1: تاريخ العينة | E1: تاريخ التحليل | F1: حتى اليوم | G1: O2 | H1: N2 | I1: O2/N2 | J1: H2 | K1: CO2 | L1: C2H4 | M1: C2H6 | N1: C2H2 | O1: CH4 | P1: CO | Q1: Result of analysis | R1: DGA | S1: C.Recommended | T1: تاريخ إعادة التحليل | U1: عمود3 | V1: الحالة | W1: CO2 / CO | X1: C2H2/ C2H4 | Y1: C2H4/ C2H6 | Z1: CH4 /H2 | AA1: عمود2
A2: اسمنت العريش | B2: 3 | C2: 220 / 11 | D2: 45895 | F2: =IFERROR(DATEDIF(D2,TODAY(),"YM") & " m " & DATEDIF(D2,TODAY(),"MD") & " D "," ") -> 3 m 20 D | G2: 51327 | H2: 258560 | I2: =G2/H2 -> 0.19851098 | J2: 122 | K2: 3092 | L2: 1 | M2: 2 | N2: 0 | O2: 1 | P2: 276 | Q2: T3 | R2: S3 | S2: R3 | T2: =IFERROR(IF(U2>=1,EDATE(D2,U2),"غير محدد"),"غير محدد") -> 45987 | U2: {=IFERROR(MID(S2,MATCH(TRUE,ISNUMBER(1*MID(S2,ROW($1:$11),1)),0),COUNT(1*MID(S2,ROW($1:$11),1))),"غير محدد")} -> 3 | V2: يحتاج الى إعادة | W2: =الشمالي!$K126/الشمالي!$P126 -> 5.26 | X2: =N2/L2 -> 0 | Y2: =L2/M2 -> 0.5 | Z2: =O2/J2 -> 0.0081967213 | AA2: =IFERROR(DATEDIF(T2,TODAY(),"MD") & " ","0 ") -> 20
A3: اسمنت بني سويف | B3: 2T | C3: 66 / 11 | D3: 45245 | F3: =IFERROR(DATEDIF(D3,TODAY(),"YM") & " m " & DATEDIF(D3,TODAY(),"MD") & " D "," ") -> 1 m 1 D | G3: 33066 | H3: 91013 | I3: =G3/H3 -> 0.36331074 | J3: 76 | K3: 3838 | L3: 4 | M3: 4 | N3: 0 | O3: 3 | P3: 201 | Q3: T3 | R3: S3 | S3: R | T3: =IFERROR(IF(U3>=1,EDATE(D3,U3),"غير محدد"),"غير محدد") -> غير محدد | U3: {=IFERROR(MID(S3,MATCH(TRUE,ISNUMBER(1*MID(S3,ROW($1:$12),1)),0),COUNT(1*MID(S3,ROW($1:$12),1))),"غير محدد")} -> غير محدد | V3: تم | W3: =الشمالي!$K3/الشمالي!$P3 -> 19.094527 | X3: =N3/L3 -> 0 | Y3: =L3/M3 -> 1 | Z3: =O3/J3 -> 0.039473684 | AA3: =IFERROR(DATEDIF(T3,TODAY(),"MD") & " ","0 ") -> 0
A4: اسمنت بني سويف | B4: 2T | C4: 66 / 11 | D4: 45403 | F4: =IFERROR(DATEDIF(D4,TODAY(),"YM") & " m " & DATEDIF(D4,TODAY(),"MD") & " D "," ") -> 7 m 25 D | G4: 47010 | H4: 76983 | I4: =G4/H4 -> 0.6106543 | J4: 41 | K4: 2390 | L4: 5 | M4: 3 | N4: 0 | O4: 1 | P4: 80 | Q4: T3 | R4: S3 | S4: R1 | T4: =IFERROR(IF(U4>=1,EDATE(D4,U4),"غير محدد"),"غير محدد") -> 45433 | U4: {=IFERROR(MID(S4,MATCH(TRUE,ISNUMBER(1*MID(S4,ROW($1:$12),1)),0),COUNT(1*MID(S4,ROW($1:$12),1))),"غير محدد")} -> 1 | V4: تم | W4: =الشمالي!$K5/الشمالي!$P5 -> 13.727891 | X4: =N4/L4 -> 0 | Y4: =L4/M4 -> 1.6666667 | Z4: =O4/J4 -> 0.024390244 | AA4: =IFERROR(DATEDIF(T4,TODAY(),"MD") & " ","0 ") -> 25
A5: اسمنت بني سويف | B5: 2T | C5: 66 / 11 | D5: 45403 | F5: =IFERROR(DATEDIF(D5,TODAY(),"YM") & " m " & DATEDIF(D5,TODAY(),"MD") & " D "," ") -> 7 m 25 D | G5: 21550 | H5: 63757 | I5: =G5/H5 -> 0.3380021 | J5: 123 | K5: 2018 | L5: 1 | M5: 3 | N5: 0 | O5: 1 | P5: 147 | Q5: T3 | R5: S3 | S5: R1 | T5: =IFERROR(IF(U5>=1,EDATE(D5,U5),"غير محدد"),"غير محدد") -> 45433 | U5: {=IFERROR(MID(S5,MATCH(TRUE,ISNUMBER(1*MID(S5,ROW($1:$12),1)),0),COUNT(1*MID(S5,ROW($1:$12),1))),"غير محدد")} -> 1 | V5: يحتاج الى إعادة | W5: =الشمالي!$K6/الشمالي!$P6 -> 5.0441176 | X5: =N5/L5 -> 0 | Y5: =L5/M5 -> 0.33333333 | Z5: =O5/J5 -> 0.0081300813 | AA5: =IFERROR(DATEDIF(T5,TODAY(),"MD") & " ","0 ") -> 25
A6: اسمنت جنوب الوادي | B6: 1T | C6: 66 / 11 | D6: 45245 | F6: =IFERROR(DATEDIF(D6,TODAY(),"YM") & " m " & DATEDIF(D6,TODAY(),"MD") & " D "," ") -> 1 m 1 D | G6: 1519 | H6: 68082 | I6: =G6/H6 -> 0.02231133 | J6: 5 | K6: 2744 | L6: 3 | M6: 2 | N6: 0 | O6: 4 | P6: 544 | Q6: T2 | R6: S2 | S6: R | T6: =IFERROR(IF(U6>=1,EDATE(D6,U6),"غير محدد"),"غير محدد") -> غير محدد | U6: {=IFERROR(MID(S6,MATCH(TRUE,ISNUMBER(1*MID(S6,ROW($1:$12),1)),0),COUNT(1*MID(S6,ROW($1:$12),1))),"غير محدد")} -> غير محدد | V6: يحتاج الى إعادة | W6: =الشمالي!$K4/الشمالي!$P4 -> 29.875 | X6: =N6/L6 -> 0 | Y6: =L6/M6 -> 1.5 | Z6: =O6/J6 -> 0.8 | AA6: =IFERROR(DATEDIF(T6,TODAY(),"MD") & " ","0 ") -> 0
A7: الشواشنة | B7: T1 | C7: 66 / 11 | D7: 45572 | F7: =IFERROR(DATEDIF(D7,TODAY(),"YM") & " m " & DATEDIF(D7,TODAY(),"MD") & " D "," ") -> 2 m 9 D | G7: 11446 | H7: 75729 | I7: =G7/H7 -> 0.15114421 | J7: 121 | K7: 3689 | L7: 2 | M7: 5 | N7: 0 | O7: 5 | P7: 352 | Q7: T2 | R7: س2 | S7: R1 | T7: =IFERROR(IF(U7>=1,EDATE(D7,U7),"غير محدد"),"غير محدد") -> 45603 | U7: {=IFERROR(MID(S7,MATCH(TRUE,ISNUMBER(1*MID(S7,ROW($1:$12),1)),0),COUNT(1*MID(S7,ROW($1:$12),1))),"غير محدد")} -> 1 | V7: يحتاج الى إعادة | W7: =الشمالي!$K14/الشمالي!$P14 -> 5.3018182 | X7: =N7/L7 -> 0 | Y7: =L7/M7 -> 0.4 | Z7: =O7/J7 -> 0.041322314 | AA7: =IFERROR(DATEDIF(T7,TODAY(),"MD") & " ","0 ") -> 9
A8: الفشن | B8: 3T | C8: 66 / 11 | D8: 45287 | F8: =IFERROR(DATEDIF(D8,TODAY(),"YM") & " m " & DATEDIF(D8,TODAY(),"MD") & " D "," ") -> 11 m 19 D | G8: 24081 | H8: 80418 | I8: =G8/H8 -> 0.29944788 | J8: 44 | K8: 3495 | L8: 2 | M8: 3 | N8: 0 | O8: 5 | P8: 312 | Q8: - | R8: S2 | S8: R | T8: =IFERROR(IF(U8>=1,EDATE(D8,U8),"غير محدد"),"غير محدد") -> غير محدد | U8: {=IFERROR(MID(S8,MATCH(TRUE,ISNUMBER(1*MID(S8,ROW($1:$12),1)),0),COUNT(1*MID(S8,ROW($1:$12),1))),"غير محدد")} -> غير محدد | V8: تم | W8: =الشمالي!$K8/الشمالي!$P8 -> 11.201923 | X8: =N8/L8 -> 0 | Y8: =L8/M8 -> 0.66666667 | Z8: =O8/J8 -> 0.11363636 | AA8: =IFERROR(DATEDIF(T8,TODAY(),"MD") & " ","0 ") -> 0
A9: الفشن | B9: 3T | C9: 66 / 11 | D9: 45403 | F9: =IFERROR(DATEDIF(D9,TODAY(),"YM") & " m " & DATEDIF(D9,TODAY(),"MD") & " D "," ") -> 7 m 25 D | G9: 34337 | H9: 79291 | I9: =G9/H9 -> 0.43305041 | J9: 53 | K9: 2784 | L9: 2 | M9: 3 | N9: 0 | O9: 2 | P9: 180 | Q9: - | R9: S2 | S9: R1 | T9: =IFERROR(IF(U9>=1,EDATE(D9,U9),"غير محدد"),"غير محدد") -> 45433 | U9: {=IFERROR(MID(S9,MATCH(TRUE,ISNUMBER(1*MID(S9,ROW($1:$12),1)),0),COUNT(1*MID(S9,ROW($1:$12),1))),"غير محدد")} -> 1 | V9: يحتاج الى إعادة | W9: =الشمالي!$K9/الشمالي!$P9 -> 15.466667 | X9: =N9/L9 -> 0 | Y9: =L9/M9 -> 0.66666667 | Z9: =O9/J9 -> 0.037735849 | AA9: =IFERROR(DATEDIF(T9,TODAY(),"MD") & " ","0 ") -> 25
A10: الفشن | B10: 3T | C10: 66 / 11 | D10: 45544 | F10: =IFERROR(DATEDIF(D10,TODAY(),"YM") & " m " & DATEDIF(D10,TODAY(),"MD") & " D "," ") -> 3 m 7 D | G10: 2710 | H10: 103123 | I10: =G10/H10 -> 0.026279298 | J10: 95 | K10: 3464 | L10: 6 | M10: 6 | N10: 0 | O10: 3 | P10: 730 | Q10: - | R10: S2 | S10: R1 | T10: =IFERROR(IF(U10>=1,EDATE(D10,U10),"غير محدد"),"غير محدد") -> 45574 | U10: {=IFERROR(MID(S10,MATCH(TRUE,ISNUMBER(1*MID(S10,ROW($1:$12),1)),0),COUNT(1*MID(S10,ROW($1:$12),1))),"غير محدد")} -> 1 | V10: يحتاج الى إعادة | W10: =الشمالي!$K10/الشمالي!$P10 -> 4.7452055 | X10: =N10/L10 -> 0 | Y10: =L10/M10 -> 1 | Z10: =O10/J10 -> 0.031578947 | AA10: =IFERROR(DATEDIF(T10,TODAY(),"MD") & " ","0 ") -> 7
A11: الفشن | B11: 4T | C11: 66 / 11 | D11: 45179 | F11: =IFERROR(DATEDIF(D11,TODAY(),"YM") & " m " & DATEDIF(D11,TODAY(),"MD") & " D "," ") -> 3 m 6 D | G11: 40544 | H11: 102294 | I11: =G11/H11 -> 0.39634778 | J11: 44 | K11: 888 | L11: 3 | M11: 2 | N11: 0 | O11: 1 | P11: 52 | Q11: - | R11: S2 | S11: R | T11: =IFERROR(IF(U11>=1,EDATE(D11,U11),"غير محدد"),"غير محدد") -> غير محدد | U11: {=IFERROR(MID(S11,MATCH(TRUE,ISNUMBER(1*MID(S11,ROW($1:$12),1)),0),COUNT(1*MID(S11,ROW($1:$12),1))),"غير محدد")} -> غير محدد | V11: تم | W11: =الشمالي!$K11/الشمالي!$P11 -> 17.076923 | X11: =N11/L11 -> 0 | Y11: =L11/M11 -> 1.5 | Z11: =O11/J11 -> 0.022727273 | AA11: =IFERROR(DATEDIF(T11,TODAY(),"MD") & " ","0 ") -> 0
A12: الفشن | B12: 4T | C12: 66 / 11 | D12: 45287 | F12: =IFERROR(DATEDIF(D12,TODAY(),"YM") & " m " & DATEDIF(D12,TODAY(),"MD") & " D "," ") -> 11 m 19 D | G12: 32205 | H12: 71389 | I12: =G12/H12 -> 0.45111992 | J12: 48 | K12: 1556 | L12: 3 | M12: 1 | N12: 0 | O12: 3 | P12: 179 | Q12: T2 | R12: S3 | S12: R | T12: =IFERROR(IF(U12>=1,EDATE(D12,U12),"غير محدد"),"غير محدد") -> غير محدد | U12: {=IFERROR(MID(S12,MATCH(TRUE,ISNUMBER(1*MID(S12,ROW($1:$12),1)),0),COUNT(1*MID(S12,ROW($1:$12),1))),"غير محدد")} -> غير محدد | V12: تم | W12: =الشمالي!$K12/الشمالي!$P12 -> 8.6927374 | X12: =N12/L12 -> 0 | Y12: =L12/M12 -> 3 | Z12: =O12/J12 -> 0.0625 | AA12: =IFERROR(DATEDIF(T12,TODAY(),"MD") & " ","0 ") -> 0
A13: الفشن | B13: 4T | C13: 66 / 11 | D13: 45403 | F13: =IFERROR(DATEDIF(D13,TODAY(),"YM") & " m " & DATEDIF(D13,TODAY(),"MD") & " D "," ") -> 7 m 25 D | G13: 48658 | H13: 69315 | I13: =G13/H13 -> 0.7019837 | J13: 43 | K13: 1285 | L13: 1 | M13: 1 | N13: 0 | O13: 2 | P13: 91 | Q13: T2 | R13: S3 | S13: R1 | T13: =IFERROR(IF(U13>=1,EDATE(D13,U13),"غير محدد"),"غير محدد") -> 45433 | U13: {=IFERROR(MID(S13,MATCH(TRUE,ISNUMBER(1*MID(S13,ROW($1:$12),1)),0),COUNT(1*MID(S13,ROW($1:$12),1))),"غير محدد")} -> 1 | V13: يحتاج الى إعادة | W13: =الشمالي!$K13/الشمالي!$P13 -> 14.120879 | X13: =N13/L13 -> 0 | Y13: =L13/M13 -> 1 | Z13: =O13/J13 -> 0.046511628 | AA13: =IFERROR(DATEDIF(T13,TODAY(),"MD") & " ","0 ") -> 25
A14: القاهرة 500 | B14: 1T PH a | C14: 500 / 220 | D14: 44973 | F14: =IFERROR(DATEDIF(D14,TODAY(),"YM") & " m " & DATEDIF(D14,TODAY(),"MD") & " D "," ") -> 10 m 0 D | G14: 1806 | H14: 65468 | I14: =G14/H14 -> 0.027585996 | J14: 183 | K14: 2916 | L14: 5 | M14: 9 | N14: 0 | O14: 26 | P14: 550 | Q14: T1 | R14: 2 | S14: R | T14: =IFERROR(IF(U14>=1,EDATE(D14,U14),"غير محدد"),"غير محدد") -> غير محدد | U14: {=IFERROR(MID(S14,MATCH(TRUE,ISNUMBER(1*MID(S14,ROW($1:$12),1)),0),COUNT(1*MID(S14,ROW($1:$12),1))),"غير محدد")} -> غير محدد | V14: تم | W14: =الشمالي!$K15/الشمالي!$P15 -> 6.8874172 | X14: =N14/L14 -> 0 | Y14: =L14/M14 -> 0.55555556 | Z14: =O14/J14 -> 0.1420765 | AA14: =IFERROR(DATEDIF(T14,TODAY(),"MD") & " ","0 ") -> 0
A15: القاهرة 500 | B15: 1T PH a | C15: 500 / 220 | D15: 45013 | F15: =IFERROR(DATEDIF(D15,TODAY(),"YM") & " m " & DATEDIF(D15,TODAY(),"MD") & " D "," ") -> 8 m 18 D | G15: 4938 | H15: 48706 | I15: =G15/H15 -> 0.10138381 | J15: 28 | K15: 1040 | L15: 3 | M15: 3 | N15: 0 | O15: 1 | P15: 151 | Q15: N | R15: 1 | S15: S | T15: =IFERROR(IF(U15>=1,EDATE(D15,U15),"غير محدد"),"غير محدد") -> غير محدد | U15: {=IFERROR(MID(S15,MATCH(TRUE,ISNUMBER(1*MID(S15,ROW($1:$12),1)),0),COUNT(1*MID(S15,ROW($1:$12),1))),"غير محدد")} -> غير محدد | V15: تم | W15: =الشمالي!$K16/الشمالي!$P16 -> 10.830131 | X15: =N15/L15 -> 0 | Y15: =L15/M15 -> 1 | Z15: =O15/J15 -> 0.035714286 | AA15: =IFERROR(DATEDIF(T15,TODAY(),"MD") & " ","0 ") -> 0
A16: القاهرة 500 | B16: 1T PH B | C16: 500 / 220 | D16: 45342 | F16: =IFERROR(DATEDIF(D16,TODAY(),"YM") & " m " & DATEDIF(D16,TODAY(),"MD") & " D "," ") -> 9 m 26 D | G16: 27737 | H16: 103148 | I16: =G16/H16 -> 0.26890487 | J16: 10 | K16: 10711 | L16: 12 | M16: 1 | N16: 0 | O16: 3 | P16: 989 | Q16: - | R16: S3 | S16: R3 | T16: =IFERROR(IF(U16>=1,EDATE(D16,U16),"غير محدد"),"غير محدد") -> 45432 | U16: {=IFERROR(MID(S16,MATCH(TRUE,ISNUMBER(1*MID(S16,ROW($1:$12),1)),0),COUNT(1*MID(S16,ROW($1:$12),1))),"غير محدد")} -> 3 | V16: يحتاج الى إعادة | W16: =الشمالي!$K17/الشمالي!$P17 -> 14.144538 | X16: =N16/L16 -> 0 | Y16: =L16/M16 -> 12 | Z16: =O16/J16 -> 0.3 | AA16: =IFERROR(DATEDIF(T16,TODAY(),"MD") & " ","0 ") -> 26
A17: القاهرة 500 | B17: 1T PH C | C17: 500 / 220 | D17: 44973 | F17: =IFERROR(DATEDIF(D17,TODAY(),"YM") & " m " & DATEDIF(D17,TODAY(),"MD") & " D "," ") -> 10 m 0 D | G17: 1116 | H17: 59966 | I17: =G17/H17 -> 0.018610546 | J17: 119 | K17: 8416 | L17: 14 | M17: 5 | N17: 0 | O17: 13 | P17: 595 | Q17: T3 | R17: 2 | S17: R | T17: =IFERROR(IF(U17>=1,EDATE(D17,U17),"غير محدد"),"غير محدد") -> غير محدد | U17: {=IFERROR(MID(S17,MATCH(TRUE,ISNUMBER(1*MID(S17,ROW($1:$12),1)),0),COUNT(1*MID(S17,ROW($1:$12),1))),"غير محدد")} -> غير محدد | V17: تم | W17: =الشمالي!$K18/الشمالي!$P18 -> 11.282759 | X17: =N17/L17 -> 0 | Y17: =L17/M17 -> 2.8 | Z17: =O17/J17 -> 0.1092437 | AA17: =IFERROR(DATEDIF(T17,TODAY(),"MD") & " ","0 ") -> 0
A18: القاهرة 500 | B18: 1T PH C | C18: 500 / 220 | D18: 45013 | F18: =IFERROR(DATEDIF(D18,TODAY(),"YM") & " m " & DATEDIF(D18,TODAY(),"MD") & " D "," ") -> 8 m 18 D | G18: 2471 | H18: 42343 | I18: =G18/H18 -> 0.058356753 | J18: 11 | K18: 1636 | L18: 2 | M18: 20 | N18: 0 | O18: 1 | P18: 145 | Q18: N | R18: 1 | S18: S | T18: =IFERROR(IF(U18>=1,EDATE(D18,U18),"غير محدد"),"غير محدد") -> غير محدد | U18: {=IFERROR(MID(S18,MATCH(TRUE,ISNUMBER(1*MID(S18,ROW($1:$12),1)),0),COUNT(1*MID(S18,ROW($1:$12),1))),"غير محدد")} -> غير محدد | V18: تم | W18: =الشمالي!$K19/الشمالي!$P19 -> 10.15122 | X18: =N18/L18 -> 0 | Y18: =L18/M18 -> 0.1 | Z18: =O18/J18 -> 0.090909091 | AA18: =IFERROR(DATEDIF(T18,TODAY(),"MD") & " ","0 ") -> 0
A19: القاهرة 500 | B19: 1T PH C | C19: 500 / 220 | D19: 45342 | F19: =IFERROR(DATEDIF(D19,TODAY(),"YM") & " m " & DATEDIF(D19,TODAY(),"MD") & " D "," ") -> 9 m 26 D | G19: 13209 | H19: 63536 | I19: =G19/H19 -> 0.20789788 | J19: 11 | K19: 6243 | L19: 2 | M19: 10 | N19: 0 | O19: 13 | P19: 615 | Q19: T1 | R19: S3 | S19: R3 | T19: =IFERROR(IF(U19>=1,EDATE(D19,U19),"غير محدد"),"غير محدد") -> 45432 | U19: {=IFERROR(MID(S19,MATCH(TRUE,ISNUMBER(1*MID(S19,ROW($1:$12),1)),0),COUNT(1*MID(S19,ROW($1:$12),1))),"غير محدد")} -> 3 | V19: تم | W19: =الشمالي!$K21/الشمالي!$P21 -> 3.7647059 | X19: =N19/L19 -> 0 | Y19: =L19/M19 -> 0.2 | Z19: =O19/J19 -> 1.1818182 | AA19: =IFERROR(DATEDIF(T19,TODAY(),"MD") & " ","0 ") -> 26
A20: القاهرة 500 | B20: 1T PH C | C20: 500 / 220 | D20: 45882 | E20: 45924 | F20: =IFERROR(DATEDIF(D20,TODAY(),"YM") & " m " & DATEDIF(D20,TODAY(),"MD") & " D "," ") -> 4 m 3 D | G20: 10651 | H20: 132059 | I20: =G20/H20 -> 0.080653344 | J20: 38 | K20: 14806 | L20: 191 | M20: 114 | N20: 0 | O20: 35 | P20: 792 | Q20: T3 | R20: S3 | S20: R3 | T20: =IFERROR(IF(U20>=1,EDATE(D20,U20),"غير محدد"),"غير محدد") -> 45974 | U20: {=IFERROR(MID(S20,MATCH(TRUE,ISNUMBER(1*MID(S20,ROW($1:$12),1)),0),COUNT(1*MID(S20,ROW($1:$12),1))),"غير محدد")} -> 3 | V20: يحتاج الى إعادة | W20: =الشمالي!$K22/الشمالي!$P22 -> 5.0090498 | X20: =N20/L20 -> 0 | Y20: =L20/M20 -> 1.6754386 | Z20: =O20/J20 -> 0.92105263 | AA20: =IFERROR(DATEDIF(T20,TODAY(),"MD") & " ","0 ") -> 3
A21: القاهرة 500 | B21: 2T PH C | C21: 500 / 220 | D21: 44973 | F21: =IFERROR(DATEDIF(D21,TODAY(),"YM") & " m " & DATEDIF(D21,TODAY(),"MD") & " D "," ") -> 10 m 0 D | G21: 3540 | H21: 64138 | I21: =G21/H21 -> 0.055193489 | J21: 494 | K21: 2048 | L21: 5 | M21: 9 | N21: 0 | O21: 43 | P21: 544 | Q21: T1 | R21: 2 | S21: R | T21: =IFERROR(IF(U21>=1,EDATE(D21,U21),"غير محدد"),"غير محدد") -> غير محدد | U21: {=IFERROR(MID(S21,MATCH(TRUE,ISNUMBER(1*MID(S21,ROW($1:$12),1)),0),COUNT(1*MID(S21,ROW($1:$12),1))),"غير محدد")} -> غير محدد | V21: تم | W21: =الشمالي!$K22/الشمالي!$P22 -> 5.0090498 | X21: =N21/L21 -> 0 | Y21: =L21/M21 -> 0.55555556 | Z21: =O21/J21 -> 0.087044534 | AA21: =IFERROR(DATEDIF(T21,TODAY(),"MD") & " ","0 ") -> 0
A22: القاهرة 500 | B22: 2T PH C | C22: 500 / 220 | D22: 45013 | F22: =IFERROR(DATEDIF(D22,TODAY(),"YM") & " m " & DATEDIF(D22,TODAY(),"MD") & " D "," ") -> 8 m 18 D | G22: 2204 | H22: 31371 | I22: =G22/H22 -> 0.070255969 | J22: 74 | K22: 1107 | L22: 3 | M22: 7 | N22: 0 | O22: 4 | P22: 221 | Q22: N | R22: 1 | S22: S | T22: =IFERROR(IF(U22>=1,EDATE(D22,U22),"غير محدد"),"غير محدد") -> غير محدد | U22: {=IFERROR(MID(S22,MATCH(TRUE,ISNUMBER(1*MID(S22,ROW($1:$12),1)),0),COUNT(1*MID(S22,ROW($1:$12),1))),"غير محدد")} -> غير محدد | V22: تم | W22: =الشمالي!$K23/الشمالي!$P23 -> 5.6191223 | X22: =N22/L22 -> 0 | Y22: =L22/M22 -> 0.42857143 | Z22: =O22/J22 -> 0.054054054 | AA22: =IFERROR(DATEDIF(T22,TODAY(),"MD") & " ","0 ") -> 0
A23: القاهرة 500 | B23: 2T PH C | C23: 500 / 220 | D23: 45342 | F23: =IFERROR(DATEDIF(D23,TODAY(),"YM") & " m " & DATEDIF(D23,TODAY(),"MD") & " D "," ") -> 9 m 26 D | G23: 5825 | H23: 71136 | I23: =G23/H23 -> 0.081885403 | J23: 305 | K23: 3585 | L23: 2 | M23: 34 | N23: 0 | O23: 37 | P23: 638 | Q23: T1 | R23: S3 | S23: R1 | T23: =IFERROR(IF(U23>=1,EDATE(D23,U23),"غير محدد"),"غير محدد") -> 45371 | U23: {=IFERROR(MID(S23,MATCH(TRUE,ISNUMBER(1*MID(S23,ROW($1:$12),1)),0),COUNT(1*MID(S23,ROW($1:$12),1))),"غير محدد")} -> 1 | V23: تم | W23: =الشمالي!$K24/الشمالي!$P24 -> 6.244898 | X23: =N23/L23 -> 0 | Y23: =L23/M23 -> 0.058823529 | Z23: =O23/J23 -> 0.12131148 | AA23: =IFERROR(DATEDIF(T23,TODAY(),"MD") & " ","0 ") -> 26
A24: القاهرة 500 | B24: 2T PH C | C24: 500 / 220 | D24: 45372 | F24: =IFERROR(DATEDIF(D24,TODAY(),"YM") & " m " & DATEDIF(D24,TODAY(),"MD") & " D "," ") -> 8 m 25 D | G24: 1240 | H24: 56428 | I24: =G24/H24 -> 0.021974906 | J24: 107 | K24: 3060 | L24: 27 | M24: 4 | N24: 0 | O24: 57 | P24: 490 | Q24: T2 | R24: S3 | S24: R&I1 | T24: =IFERROR(IF(U24>=1,EDATE(D24,U24),"غير محدد"),"غير محدد") -> 45403 | U24: {=IFERROR(MID(S24,MATCH(TRUE,ISNUMBER(1*MID(S24,ROW($1:$12),1)),0),COUNT(1*MID(S24,ROW($1:$12),1))),"غير محدد")} -> 1 | V24: تم | W24: =الشمالي!$K26/الشمالي!$P26 -> 4.4288425 | X24: =N24/L24 -> 0 | Y24: =L24/M24 -> 6.75 | Z24: =O24/J24 -> 0.53271028 | AA24: =IFERROR(DATEDIF(T24,TODAY(),"MD") & " ","0 ") -> 25
A25: القاهرة 500 | B25: 2T PH C | C25: 500 / 220 | D25: 45406 | F25: =IFERROR(DATEDIF(D25,TODAY(),"YM") & " m " & DATEDIF(D25,TODAY(),"MD") & " D "," ") -> 7 m 22 D | G25: 8075 | H25: 66021 | I25: =G25/H25 -> 0.12230957 | J25: 400 | K25: 2812 | L25: 7 | M25: 22 | N25: 0 | O25: 63 | P25: 594 | Q25: T1 | R25: S3 | S25: I | T25: =IFERROR(IF(U25>=1,EDATE(D25,U25),"غير محدد"),"غير محدد") -> غير محدد | U25: {=IFERROR(MID(S25,MATCH(TRUE,ISNUMBER(1*MID(S25,ROW($1:$12),1)),0),COUNT(1*MID(S25,ROW($1:$12),1))),"غير محدد")} -> غير محدد | V25: تم | W25: =الشمالي!$K27/الشمالي!$P27 -> 14.362205 | X25: =N25/L25 -> 0 | Y25: =L25/M25 -> 0.31818182 | Z25: =O25/J25 -> 0.1575 | AA25: =IFERROR(DATEDIF(T25,TODAY(),"MD") & " ","0 ") -> 0
A26: القاهرة 500 | B26: 2T PH C | C26: 500 / 220 | D26: 45756 | F26: =IFERROR(DATEDIF(D26,TODAY(),"YM") & " m " & DATEDIF(D26,TODAY(),"MD") & " D "," ") -> 8 m 7 D | G26: 1984 | H26: 50540 | I26: =G26/H26 -> 0.039256035 | J26: 325 | K26: 4668 | L26: 11 | M26: 53 | N26: 0 | O26: 2 | P26: 1054 | Q26: T3 | R26: S3 | S26: R1 | T26: =IFERROR(IF(U26>=1,EDATE(D26,U26),"غير محدد"),"غير محدد") -> 45786 | U26: {=IFERROR(MID(S26,MATCH(TRUE,ISNUMBER(1*MID(S26,ROW($1:$12),1)),0),COUNT(1*MID(S26,ROW($1:$12),1))),"غير محدد")} -> 1 | V26: يحتاج الى إعادة | W26: =الشمالي!$K28/الشمالي!$P28 -> 7.475 | X26: =N26/L26 -> 0 | Y26: =L26/M26 -> 0.20754717 | Z26: =O26/J26 -> 0.0061538462 | AA26: =IFERROR(DATEDIF(T26,TODAY(),"MD") & " ","0 ") -> 7
A27: الكوم الأحمر | B27: 4t | C27: 66 / 11 | D27: 45208 | F27: =IFERROR(DATEDIF(D27,TODAY(),"YM") & " m " & DATEDIF(D27,TODAY(),"MD") & " D "," ") -> 2 m 7 D | G27: 885 | H27: 92884 | I27: =G27/H27 -> 0.0095280134 | J27: 147 | K27: 1824 | L27: 2 | M27: 15 | N27: 0 | O27: 1 | P27: 127 | Q27: - | R27: S2 | S27: R | T27: =IFERROR(IF(U27>=1,EDATE(D27,U27),"غير محدد"),"غير محدد") -> غير محدد | U27: {=IFERROR(MID(S27,MATCH(TRUE,ISNUMBER(1*MID(S27,ROW($1:$12),1)),0),COUNT(1*MID(S27,ROW($1:$12),1))),"غير محدد")} -> غير محدد | V27: تم | W27: =الشمالي!$K28/الشمالي!$P28 -> 7.475 | X27: =N27/L27 -> 0 | Y27: =L27/M27 -> 0.13333333 | Z27: =O27/J27 -> 0.0068027211 | AA27: =IFERROR(DATEDIF(T27,TODAY(),"MD") & " ","0 ") -> 0
A28: الكوم الأحمر | B28: 4t | C28: 66 / 11 | D28: 45287 | F28: =IFERROR(DATEDIF(D28,TODAY(),"YM") & " m " & DATEDIF(D28,TODAY(),"MD") & " D "," ") -> 11 m 19 D | G28: 13216 | H28: 87028 | I28: =G28/H28 -> 0.15185917 | J28: 251 | K28: 2990 | L28: 3 | M28: 28 | N28: 0 | O28: 11 | P28: 400 | Q28: T2 | R28: S3 | S28: R&I | T28: =IFERROR(IF(U28>=1,EDATE(D28,U28),"غير محدد"),"غير محدد") -> غير محدد | U28: {=IFERROR(MID(S28,MATCH(TRUE,ISNUMBER(1*MID(S28,ROW($1:$12),1)),0),COUNT(1*MID(S28,ROW($1:$12),1))),"غير محدد")} -> غير محدد | V28: تم | W28: =الشمالي!$K29/الشمالي!$P29 -> 12.897849 | X28: =N28/L28 -> 0 | Y28: =L28/M28 -> 0.10714286 | Z28: =O28/J28 -> 0.043824701 | AA28: =IFERROR(DATEDIF(T28,TODAY(),"MD") & " ","0 ") -> 0
A29: الكوم الأحمر | B29: 4t | C29: 66 / 11 | D29: 45403 | F29: =IFERROR(DATEDIF(D29,TODAY(),"YM") & " m " & DATEDIF(D29,TODAY(),"MD") & " D "," ") -> 7 m 25 D | G29: 18388 | H29: 61622 | I29: =G29/H29 -> 0.29839992 | J29: 196 | K29: 2399 | L29: 1 | M29: 18 | N29: 0 | O29: 5 | P29: 186 | Q29: T2 | R29: S3 | S29: R1 | T29: =IFERROR(IF(U29>=1,EDATE(D29,U29),"غير محدد"),"غير محدد") -> 45433 | U29: {=IFERROR(MID(S29,MATCH(TRUE,ISNUMBER(1*MID(S29,ROW($1:$12),1)),0),COUNT(1*MID(S29,ROW($1:$12),1))),"غير محدد")} -> 1 | V29: يحتاج الى إعادة | W29: =الشمالي!$K30/الشمالي!$P30 -> 9.7190476 | X29: =N29/L29 -> 0 | Y29: =L29/M29 -> 0.055555556 | Z29: =O29/J29 -> 0.025510204 | AA29: =IFERROR(DATEDIF(T29,TODAY(),"MD") & " ","0 ") -> 25
A30: الكوم الأحمر | B30: 5T | C30: 66 / 11 | D30: 45208 | F30: =IFERROR(DATEDIF(D30,TODAY(),"YM") & " m " & DATEDIF(D30,TODAY(),"MD") & " D "," ") -> 2 m 7 D | G30: 792 | H30: 96679 | I30: =G30/H30 -> 0.0081920583 | J30: 114 | K30: 2041 | L30: 2 | M30: 9 | N30: 0 | O30: 1 | P30: 210 | Q30: - | R30: S2 | S30: R | T30: =IFERROR(IF(U30>=1,EDATE(D30,U30),"غير محدد"),"غير محدد") -> غير محدد | U30: {=IFERROR(MID(S30,MATCH(TRUE,ISNUMBER(1*MID(S30,ROW($1:$12),1)),0),COUNT(1*MID(S30,ROW($1:$12),1))),"غير محدد")} -> غير محدد | V30: تم | W30: =الشمالي!$K31/الشمالي!$P31 -> 7.407767 | X30: =N30/L30 -> 0 | Y30: =L30/M30 -> 0.22222222 | Z30: =O30/J30 -> 0.0087719298 | AA30: =IFERROR(DATEDIF(T30,TODAY(),"MD") & " ","0 ") -> 0
A31: الكوم الأحمر | B31: 5T | C31: 66 / 11 | D31: 45287 | F31: =IFERROR(DATEDIF(D31,TODAY(),"YM") & " m " & DATEDIF(D31,TODAY(),"MD") & " D "," ") -> 11 m 19 D | G31: 16117 | H31: 77962 | I31: =G31/H31 -> 0.20672892 | J31: 134 | K31: 3052 | L31: 1 | M31: 17 | N31: 0 | O31: 14 | P31: 412 | Q31: T2 | R31: S3 | S31: R&I | T31: =IFERROR(IF(U31>=1,EDATE(D31,U31),"غير محدد"),"غير محدد") -> غير محدد | U31: {=IFERROR(MID(S31,MATCH(TRUE,ISNUMBER(1*MID(S31,ROW($1:$12),1)),0),COUNT(1*MID(S31,ROW($1:$12),1))),"غير محدد")} -> غير محدد | V31: تم | W31: =الشمالي!$K32/الشمالي!$P32 -> 13.118557 | X31: =N31/L31 -> 0 | Y31: =L31/M31 -> 0.058823529 | Z31: =O31/J31 -> 0.10447761 | AA31: =IFERROR(DATEDIF(T31,TODAY(),"MD") & " ","0 ") -> 0
A32: الكوم الأحمر | B32: 5T | C32: 66 / 11 | D32: 45403 | F32: =IFERROR(DATEDIF(D32,TODAY(),"YM") & " m " & DATEDIF(D32,TODAY(),"MD") & " D "," ") -> 7 m 25 D | G32: 19043 | H32: 65523 | I32: =G32/H32 -> 0.29063077 | J32: 178 | K32: 2545 | L32: 1 | M32: 5 | N32: 0 | O32: 3 | P32: 194 | Q32: T2 | R32: S3 | S32: R1 | T32: =IFERROR(IF(U32>=1,EDATE(D32,U32),"غير محدد"),"غير محدد") -> 45433 | U32: {=IFERROR(MID(S32,MATCH(TRUE,ISNUMBER(1*MID(S32,ROW($1:$12),1)),0),COUNT(1*MID(S32,ROW($1:$12),1))),"غير محدد")} -> 1 | V32: يحتاج الى إعادة | W32: =الشمالي!$K33/الشمالي!$P33 -> 13.815385 | X32: =N32/L32 -> 0 | Y32: =L32/M32 -> 0.2 | Z32: =O32/J32 -> 0.016853933 | AA32: =IFERROR(DATEDIF(T32,TODAY(),"MD") & " ","0 ") -> 25
A33: الكوم الأحمر | B33: 6T | C33: 66 / 11 | D33: 45208 | F33: =IFERROR(DATEDIF(D33,TODAY(),"YM") & " m " & DATEDIF(D33,TODAY(),"MD") & " D "," ") -> 2 m 7 D | G33: 822 | H33: 82803 | I33: =G33/H33 -> 0.0099271766 | J33: 174 | K33: 1796 | L33: 2 | M33: 3 | N33: 0 | O33: 1 | P33: 130 | Q33: - | R33: S2 | S33: R | T33: =IFERROR(IF(U33>=1,EDATE(D33,U33),"غير محدد"),"غير محدد") -> غير محدد | U33: {=IFERROR(MID(S33,MATCH(TRUE,ISNUMBER(1*MID(S33,ROW($1:$12),1)),0),COUNT(1*MID(S33,ROW($1:$12),1))),"غير محدد")} -> غير محدد | V33: تم | W33: =الشمالي!$K34/الشمالي!$P34 -> 9.1030928 | X33: =N33/L33 -> 0 | Y33: =L33/M33 -> 0.66666667 | Z33: =O33/J33 -> 0.0057471264 | AA33: =IFERROR(DATEDIF(T33,TODAY(),"MD") & " ","0 ") -> 0
A34: الكوم الأحمر | B34: 6T | C34: 66 / 11 | D34: 45287 | F34: =IFERROR(DATEDIF(D34,TODAY(),"YM") & " m " & DATEDIF(D34,TODAY(),"MD") & " D "," ") -> 11 m 19 D | G34: 21519 | H34: 68743 | I34: =G34/H34 -> 0.31303551 | J34: 81 | K34: 2649 | L34: 2 | M34: 3 | N34: 0 | O34: 4 | P34: 291 | Q34: - | R34: S2 | S34: R | T34: =IFERROR(IF(U34>=1,EDATE(D34,U34),"غير محدد"),"غير محدد") -> غير محدد | U34: {=IFERROR(MID(S34,MATCH(TRUE,ISNUMBER(1*MID(S34,ROW($1:$12),1)),0),COUNT(1*MID(S34,ROW($1:$12),1))),"غير محدد")} -> غير محدد | V34: تم | W34: =الشمالي!$K35/الشمالي!$P35 -> 13.410405 | X34: =N34/L34 -> 0 | Y34: =L34/M34 -> 0.66666667 | Z34: =O34/J34 -> 0.049382716 | AA34: =IFERROR(DATEDIF(T34,TODAY(),"MD") & " ","0 ") -> 0
A35: الكوم الأحمر | B35: 6T | C35: 66 / 11 | D35: 45403 | F35: =IFERROR(DATEDIF(D35,TODAY(),"YM") & " m " & DATEDIF(D35,TODAY(),"MD") & " D "," ") -> 7 m 25 D | G35: 21454 | H35: 64062 | I35: =G35/H35 -> 0.33489432 | J35: 65 | K35: 2320 | L35: 1 | M35: 3 | N35: 0 | O35: 1 | P35: 173 | Q35: - | R35: S2 | S35: R1 | T35: =IFERROR(IF(U35>=1,EDATE(D35,U35),"غير محدد"),"غير محدد") -> 45433 | U35: {=IFERROR(MID(S35,MATCH(TRUE,ISNUMBER(1*MID(S35,ROW($1:$12),1)),0),COUNT(1*MID(S35,ROW($1:$12),1))),"غير محدد")} -> 1 | V35: يحتاج الى إعادة | W35: =الشمالي!$K36/الشمالي!$P36 -> 20.25 | X35: =N35/L35 -> 0 | Y35: =L35/M35 -> 0.33333333 | Z35: =O35/J35 -> 0.015384615 | AA35: =IFERROR(DATEDIF(T35,TODAY(),"MD") & " ","0 ") -> 25
A36: الواسطى | B36: 3T | C36: 66 / 11 | D36: 45340 | F36: =IFERROR(DATEDIF(D36,TODAY(),"YM") & " m " & DATEDIF(D36,TODAY(),"MD") & " D "," ") -> 9 m 28 D | G36: 19108 | H36: 85274 | I36: =G36/H36 -> 0.22407768 | J36: 20 | K36: 3159 | L36: 4 | M36: 23 | N36: 0 | O36: 1 | P36: 156 | Q36: - | R36: S2 | S36: R6 | T36: =IFERROR(IF(U36>=1,EDATE(D36,U36),"غير محدد"),"غير محدد") -> 45522 | U36: {=IFERROR(MID(S36,MATCH(TRUE,ISNUMBER(1*MID(S36,ROW($1:$12),1)),0),COUNT(1*MID(S36,ROW($1:$12),1))),"غير محدد")} -> 6 | V36: يحتاج الى إعادة | W36: =الشمالي!$K37/الشمالي!$P37 -> 14.013699 | X36: =N36/L36 -> 0 | Y36: =L36/M36 -> 0.17391304 | Z36: =O36/J36 -> 0.05 | AA36: =IFERROR(DATEDIF(T36,TODAY(),"MD") & " ","0 ") -> 28
A37: اهناسيا | B37: 1T | C37: 66 / 11 | D37: 45208 | F37: =IFERROR(DATEDIF(D37,TODAY(),"YM") & " m " & DATEDIF(D37,TODAY(),"MD") & " D "," ") -> 2 m 7 D | G37: 3633 | H37: 111565 | I37: =G37/H37 -> 0.032563976 | J37: 216 | K37: 2046 | L37: 2 | M37: 7 | N37: 0 | O37: 1 | P37: 146 | Q37: T3 | R37: S3 | S37: R&I | T37: =IFERROR(IF(U37>=1,EDATE(D37,U37),"غير محدد"),"غير محدد") -> غير محدد | U37: {=IFERROR(MID(S37,MATCH(TRUE,ISNUMBER(1*MID(S37,ROW($1:$12),1)),0),COUNT(1*MID(S37,ROW($1:$12),1))),"غير محدد")} -> غير محدد | V37: تم | W37: =الشمالي!$K38/الشمالي!$P38 -> 9.4778761 | X37: =N37/L37 -> 0 | Y37: =L37/M37 -> 0.28571429 | Z37: =O37/J37 -> 0.0046296296 | AA37: =IFERROR(DATEDIF(T37,TODAY(),"MD") & " ","0 ") -> 0
A38: اهناسيا | B38: 1T | C38: 66 / 11 | D38: 45287 | F38: =IFERROR(DATEDIF(D38,TODAY(),"YM") & " m " & DATEDIF(D38,TODAY(),"MD") & " D "," ") -> 11 m 19 D | G38: 10627 | H38: 50418 | I38: =G38/H38 -> 0.2107779 | J38: 51 | K38: 1071 | L38: 3 | M38: 6 | N38: 0 | O38: 3 | P38: 113 | Q38: - | R38: S2 | S38: R | T38: =IFERROR(IF(U38>=1,EDATE(D38,U38),"غير محدد"),"غير محدد") -> غير محدد | U38: {=IFERROR(MID(S38,MATCH(TRUE,ISNUMBER(1*MID(S38,ROW($1:$12),1)),0),COUNT(1*MID(S38,ROW($1:$12),1))),"غير محدد")} -> غير محدد | V38: يحتاج الى إعادة | W38: =الشمالي!$K39/الشمالي!$P39 -> 12.338028 | X38: =N38/L38 -> 0 | Y38: =L38/M38 -> 0.5 | Z38: =O38/J38 -> 0.058823529 | AA38: =IFERROR(DATEDIF(T38,TODAY(),"MD") & " ","0 ") -> 0
... A42: اهناسيا | B42: 3T | C42: 66 / 11 | D42: 45208 | F42: =IFERROR(DATEDIF(D42,TODAY(),"YM") & " m " & DATEDIF(D42,TODAY(),"MD") & " D "," ") -> 2 m 7 D | G42: 8244 | H42: 96479 | I42: =G42/H42 -> 0.085448647 | J42: 86 | K42: 2311 | L42: 3 | M42: 2 | N42: 0 | O42: 1 | P42: 160 | Q42: - | R42: S2 | S42: R | T42: =IFERROR(IF(U42>=1,EDATE(D42,U42),"غير محدد"),"غير محدد") -> غير محدد | U42: {=IFERROR(MID(S42,MATCH(TRUE,ISNUMBER(1*MID(S42,ROW($1:$12),1)),0),COUNT(1*MID(S42,ROW($1:$12),1))),"غير محدد")} -> غير محدد | V42: يحتاج الى إعادة | W42: =الشمالي!$K43/الشمالي!$P43 -> 14.627119 | X42: =N42/L42 -> 0 | Y42: =L42/M42 -> 1.5 | Z42: =O42/J42 -> 0.011627907 | AA42: =IFERROR(DATEDIF(T42,TODAY(),"MD") & " ","0 ") -> 0
A43: اهناسيا | B43: 4T | C43: 66 / 11 | D43: 45208 | F43: =IFERROR(DATEDIF(D43,TODAY(),"YM") & " m " & DATEDIF(D43,TODAY(),"MD") & " D "," ") -> 2 m 7 D | G43: 20314 | H43: 168945 | I43: =G43/H43 -> 0.12024031 | J43: 134 | K43: 2589 | L43: 2 | M43: 3 | N43: 0 | O43: 2 | P43: 177 | Q43: - | R43: S2 | S43: R | T43: =IFERROR(IF(U43>=1,EDATE(D43,U43),"غير محدد"),"غير محدد") -> غير محدد | U43: {=IFERROR(MID(S43,MATCH(TRUE,ISNUMBER(1*MID(S43,ROW($1:$12),1)),0),COUNT(1*MID(S43,ROW($1:$12),1))),"غير محدد")} -> غير محدد | V43: يحتاج الى إعادة | W43: =الشمالي!$K45/الشمالي!$P45 -> 19.760148 | X43: =N43/L43 -> 0 | Y43: =L43/M43 -> 0.66666667 | Z43: =O43/J43 -> 0.014925373 | AA43: =IFERROR(DATEDIF(T43,TODAY(),"MD") & " ","0 ") -> 0
...

Sheet المنيا
A1: المحطة | B1: المحول | C1: الجهد | D1: تاريخ العينة | E1: حتى اليوم | F1: O2 | G1: N2 | H1: O2/N2 | I1: H2 | J1: CO2 | K1: C2H4 | L1: C2H6 | M1: C2H2 | N1: CH4 | O1: CO | P1: Result of analysis | Q1: DGA | R1: C.Recommended | S1: تاريخ إعادة التحاليل | T1: عمود1 | U1: الحالة | V1: CO2 / CO | W1: C2H2/ C2H4 | X1: C2H4/ C2H6 | Y1: CH4 /H2 | Z1: عمود2
A2: اسمنت المنيا | B2: 1T | C2: 132 / 6.3 | D2: 45372 | E2: =IFERROR(DATEDIF(D2,TODAY(),"YM") & " m " & DATEDIF(D2,TODAY(),"MD") & " D "," ") -> 8 m 25 D | F2: 22362 | G2: 66220 | H2: =الجدول1[[#This Row],[O2]]/الجدول1[[#This Row],[N2]] -> 0.33769254 | I2: 15 | J2: 2109 | K2: 2 | L2: 2 | M2: 0 | N2: 2 | O2: 85 | P2: N | Q2: S1 | R2: A | S2: =IFERROR(IF(T2>=1,EDATE(D2,T2),"غير محدد"),"غير محدد") -> غير محدد | T2: {=IFERROR(MID(R2,MATCH(TRUE,ISNUMBER(1*MID(R2,ROW($1:$13),1)),0),COUNT(1*MID(R2,ROW($1:$13),1))),"غير محدد")} -> غير محدد | U2: تم | V2: =الجدول1[[#This Row],[CO2]]/الجدول1[[#This Row],[CO]] -> 24.811765 | W2: =الجدول1[[#This Row],[C2H2]]/الجدول1[[#This Row],[C2H4]] -> 0 | X2: =الجدول1[[#This Row],[C2H4]]/الجدول1[[#This Row],[C2H6]] -> 1 | Y2: =الجدول1[[#This Row],[CH4]]/الجدول1[[#This Row],[H2]] -> 0.13333333 | Z2: =IFERROR(DATEDIF(S2,TODAY(),"MD") & " ","0 ") -> 0
A3: اسمنت المنيا | B3: 2T | C3: 132 / 6.3 | D3: 45372 | E3: =IFERROR(DATEDIF(D3,TODAY(),"YM") & " m " & DATEDIF(D3,TODAY(),"MD") & " D "," ") -> 8 m 25 D | F3: 29848 | G3: 81574 | H3: =الجدول1[[#This Row],[O2]]/الجدول1[[#This Row],[N2]] -> 0.3659009 | I3: 8 | J3: 2292 | K3: 2 | L3: 2 | M3: 0 | N3: 1 | O3: 128 | P3: N | Q3: S1 | R3: A | S3: =IFERROR(IF(T3>=1,EDATE(D3,T3),"غير محدد"),"غير محدد") -> غير محدد | T3: {=IFERROR(MID(R3,MATCH(TRUE,ISNUMBER(1*MID(R3,ROW($1:$13),1)),0),COUNT(1*MID(R3,ROW($1:$13),1))),"غير محدد")} -> غير محدد | U3: تم | V3: =الجدول1[[#This Row],[CO2]]/الجدول1[[#This Row],[CO]] -> 17.90625 | W3: =الجدول1[[#This Row],[C2H2]]/الجدول1[[#This Row],[C2H4]] -> 0 | X3: =الجدول1[[#This Row],[C2H4]]/الجدول1[[#This Row],[C2H6]] -> 1 | Y3: =الجدول1[[#This Row],[CH4]]/الجدول1[[#This Row],[H2]] -> 0.125 | Z3: =IFERROR(DATEDIF(S3,TODAY(),"MD") & " ","0 ") -> 0
A4: الباويطي | B4: 1T | C4: 33 / 11 | D4: 45286 | E4: =IFERROR(DATEDIF(D4,TODAY(),"YM") & " m " & DATEDIF(D4,TODAY(),"MD") & " D "," ") -> 11 m 20 D | F4: 25832 | G4: 80093 | H4: =الجدول1[[#This Row],[O2]]/الجدول1[[#This Row],[N2]] -> 0.32252506 | I4: 53 | J4: 4652 | K4: 2 | L4: 3 | M4: 0 | N4: 2 | O4: 303 | P4: T3 | Q4: S3 | R4: R | S4: =IFERROR(IF(T4>=1,EDATE(D4,T4),"غير محدد"),"غير محدد") -> غير محدد | T4: {=IFERROR(MID(R4,MATCH(TRUE,ISNUMBER(1*MID(R4,ROW($1:$13),1)),0),COUNT(1*MID(R4,ROW($1:$13),1))),"غير محدد")} -> غير محدد | U4: تم | V4: =الجدول1[[#This Row],[CO2]]/الجدول1[[#This Row],[CO]] -> 15.353135 | W4: =الجدول1[[#This Row],[C2H2]]/الجدول1[[#This Row],[C2H4]] -> 0 | X4: =الجدول1[[#This Row],[C2H4]]/الجدول1[[#This Row],[C2H6]] -> 0.66666667 | Y4: =الجدول1[[#This Row],[CH4]]/الجدول1[[#This Row],[H2]] -> 0.037735849 | Z4: =IFERROR(DATEDIF(S4,TODAY(),"MD") & " ","0 ") -> 0
A5: الباويطي | B5: 2T | C5: 33 / 11 | D5: 45286 | E5: =IFERROR(DATEDIF(D5,TODAY(),"YM") & " m " & DATEDIF(D5,TODAY(),"MD") & " D "," ") -> 11 m 20 D | F5: 25916 | G5: 77958 | H5: =الجدول1[[#This Row],[O2]]/الجدول1[[#This Row],[N2]] -> 0.33243541 | I5: 53 | J5: 1626 | K5: 2 | L5: 3 | M5: 0 | N5: 3 | O5: 141 | P5: T2 | Q5: S3 | R5: R | S5: =IFERROR(IF(T5>=1,EDATE(D5,T5),"غير محدد"),"غير محدد") -> غير محدد | T5: {=IFERROR(MID(R5,MATCH(TRUE,ISNUMBER(1*MID(R5,ROW($1:$13),1)),0),COUNT(1*MID(R5,ROW($1:$13),1))),"غير محدد")} -> غير محدد | U5: يحتاج الى إعادة | V5: =الجدول1[[#This Row],[CO2]]/الجدول1[[#This Row],[CO]] -> 11.531915 | W5: =الجدول1[[#This Row],[C2H2]]/الجدول1[[#This Row],[C2H4]] -> 0 | X5: =الجدول1[[#This Row],[C2H4]]/الجدول1[[#This Row],[C2H6]] -> 0.66666667 | Y5: =الجدول1[[#This Row],[CH4]]/الجدول1[[#This Row],[H2]] -> 0.056603774 | Z5: =IFERROR(DATEDIF(S5,TODAY(),"MD") & " ","0 ") -> 0
A6: القناة للسكر | B6: 2T | C6: 220 / 33 | D6: 45480 | E6: =IFERROR(DATEDIF(D6,TODAY(),"YM") & " m " & DATEDIF(D6,TODAY(),"MD") & " D "," ") -> 5 m 9 D | F6: 18330 | G6: 81658 | H6: =الجدول1[[#This Row],[O2]]/الجدول1[[#This Row],[N2]] -> 0.2244728 | I6: 22 | J6: 1968 | K6: 1 | L6: 6 | M6: 0 | N6: 1 | O6: 179 | P6: N | Q6: S1 | R6: A | S6: =IFERROR(IF(T6>=1,EDATE(D6,T6),"غير محدد"),"غير محدد") -> غير محدد | T6: {=IFERROR(MID(R6,MATCH(TRUE,ISNUMBER(1*MID(R6,ROW($1:$13),1)),0),COUNT(1*MID(R6,ROW($1:$13),1))),"غير محدد")} -> غير محدد | U6: تم | V6: =الجدول1[[#This Row],[CO2]]/الجدول1[[#This Row],[CO]] -> 10.994413 | W6: =الجدول1[[#This Row],[C2H2]]/الجدول1[[#This Row],[C2H4]] -> 0 | X6: =الجدول1[[#This Row],[C2H4]]/الجدول1[[#This Row],[C2H6]] -> 0.16666667 | Y6: =الجدول1[[#This Row],[CH4]]/الجدول1[[#This Row],[H2]] -> 0.045454545 | Z6: =IFERROR(DATEDIF(S6,TODAY(),"MD") & " ","0 ") -> 0
A7: القناة للسكر | B7: 2T | C7: 220 / 33 | D7: 45875 | E7: =IFERROR(DATEDIF(D7,TODAY(),"YM") & " m " & DATEDIF(D7,TODAY(),"MD") & " D "," ") -> 4 m 10 D | F7: 30226 | G7: 117829 | H7: =الجدول1[[#This Row],[O2]]/الجدول1[[#This Row],[N2]] -> 0.25652429 | I7: 27 | J7: 5990 | K7: 2 | L7: 1 | M7: 0 | N7: 1 | O7: 824 | P7: T3 | Q7: S3 | R7: R3 | S7: =IFERROR(IF(T7>=1,EDATE(D7,T7),"غير محدد"),"غير محدد") -> 45967 | T7: {=IFERROR(MID(R7,MATCH(TRUE,ISNUMBER(1*MID(R7,ROW($1:$13),1)),0),COUNT(1*MID(R7,ROW($1:$13),1))),"غير محدد")} -> 3 | U7: يحتاج الى إعادة | V7: =الجدول1[[#This Row],[CO2]]/الجدول1[[#This Row],[CO]] -> 7.2694175 | W7: =الجدول1[[#This Row],[C2H2]]/الجدول1[[#This Row],[C2H4]] -> 0 | X7: =الجدول1[[#This Row],[C2H4]]/الجدول1[[#This Row],[C2H6]] -> 2 | Y7: =الجدول1[[#This Row],[CH4]]/الجدول1[[#This Row],[H2]] -> 0.037037037 | Z7: =IFERROR(DATEDIF(S7,TODAY(),"MD") & " ","0 ") -> 10
A8: الواحات | B8: 2T | C8: 132 / 33 | D8: 45286 | E8: =IFERROR(DATEDIF(D8,TODAY(),"YM") & " m " & DATEDIF(D8,TODAY(),"MD") & " D "," ") -> 11 m 20 D | F8: 27497 | G8: 70251 | H8: =الجدول1[[#This Row],[O2]]/الجدول1[[#This Row],[N2]] -> 0.3914108 | I8: 77 | J8: 2303 | K8: 4 | L8: 3 | M8: 0 | N8: 2 | O8: 250 | P8: T2 | Q8: S3 | R8: R | S8: =IFERROR(IF(T8>=1,EDATE(D8,T8),"غير محدد"),"غير محدد") -> غير محدد | T8: {=IFERROR(MID(R8,MATCH(TRUE,ISNUMBER(1*MID(R8,ROW($1:$13),1)),0),COUNT(1*MID(R8,ROW($1:$13),1))),"غير محدد")} -> غير محدد | U8: يحتاج الى إعادة | V8: =الجدول1[[#This Row],[CO2]]/الجدول1[[#This Row],[CO]] -> 9.212 | W8: =الجدول1[[#This Row],[C2H2]]/الجدول1[[#This Row],[C2H4]] -> 0 | X8: =الجدول1[[#This Row],[C2H4]]/الجدول1[[#This Row],[C2H6]] -> 1.3333333 | Y8: =الجدول1[[#This Row],[CH4]]/الجدول1[[#This Row],[H2]] -> 0.025974026 | Z8: =IFERROR(DATEDIF(S8,TODAY(),"MD") & " ","0 ") -> 0
A9: أبو قرقاص 66 | B9: 1T | C9: 66 / 11 | D9: 45208 | E9: =IFERROR(DATEDIF(D9,TODAY(),"YM") & " m " & DATEDIF(D9,TODAY(),"MD") & " D "," ") -> 2 m 7 D | F9: 3242 | G9: 140739 | H9: =الجدول1[[#This Row],[O2]]/الجدول1[[#This Row],[N2]] -> 0.023035548 | I9: 220 | J9: 7393 | K9: 4 | L9: 4 | M9: 0 | N9: 2 | O9: 618 | P9: T3 | Q9: 2 | R9: R | S9: =IFERROR(IF(T9>=1,EDATE(D9,T9),"غير محدد"),"غير محدد") -> غير محدد | T9: {=IFERROR(MID(R9,MATCH(TRUE,ISNUMBER(1*MID(R9,ROW($1:$13),1)),0),COUNT(1*MID(R9,ROW($1:$13),1))),"غير محدد")} -> غير محدد | U9: يحتاج الى إعادة | V9: =الجدول1[[#This Row],[CO2]]/الجدول1[[#This Row],[CO]] -> 11.962783 | W9: =الجدول1[[#This Row],[C2H2]]/الجدول1[[#This Row],[C2H4]] -> 0 | X9: =الجدول1[[#This Row],[C2H4]]/الجدول1[[#This Row],[C2H6]] -> 1 | Y9: =الجدول1[[#This Row],[CH4]]/الجدول1[[#This Row],[H2]] -> 0.0090909091 | Z9: =IFERROR(DATEDIF(S9,TODAY(),"MD") & " ","0 ") -> 0
A10: أبو قرقاص 66 | B10: 2T | C10: 66 / 11 | D10: 45412 | E10: =IFERROR(DATEDIF(D10,TODAY(),"YM") & " m " & DATEDIF(D10,TODAY(),"MD") & " D "," ") -> 7 m 16 D | F10: 17313 | G10: 76659 | H10: =الجدول1[[#This Row],[O2]]/الجدول1[[#This Row],[N2]] -> 0.22584432 | I10: 47 | J10: 2544 | K10: 7 | L10: 4 | M10: 0 | N10: 1 | O10: 260 | P10: - | Q10: S2 | R10: R1 | S10: =IFERROR(IF(T10>=1,EDATE(D10,T10),"غير محدد"),"غير محدد") -> 45442 | T10: {=IFERROR(MID(R10,MATCH(TRUE,ISNUMBER(1*MID(R10,ROW($1:$13),1)),0),COUNT(1*MID(R10,ROW($1:$13),1))),"غير محدد")} -> 1 | U10: تم | V10: =الجدول1[[#This Row],[CO2]]/الجدول1[[#This Row],[CO]] -> 9.7846154 | W10: =الجدول1[[#This Row],[C2H2]]/الجدول1[[#This Row],[C2H4]] -> 0 | X10: =الجدول1[[#This Row],[C2H4]]/الجدول1[[#This Row],[C2H6]] -> 1.75 | Y10: =الجدول1[[#This Row],[CH4]]/الجدول1[[#This Row],[H2]] -> 0.021276596 | Z10: =IFERROR(DATEDIF(S10,TODAY(),"MD") & " ","0 ") -> 16
A11: أبو قرقاص 66 | B11: 2T | C11: 66 / 11 | D11: 45554 | E11: =IFERROR(DATEDIF(D11,TODAY(),"YM") & " m " & DATEDIF(D11,TODAY(),"MD") & " D "," ") -> 2 m 27 D | F11: 1658 | G11: 73080 | H11: =الجدول1[[#This Row],[O2]]/الجدول1[[#This Row],[N2]] -> 0.022687466 | I11: 247 | J11: 2004 | K11: 1 | L11: 5 | M11: 0 | N11: 5 | O11: 275 | P11: T1 | Q11: S3 | R11: R1 | S11: =IFERROR(IF(T11>=1,EDATE(D11,T11),"غير محدد"),"غير محدد") -> 45584 | T11: {=IFERROR(MID(R11,MATCH(TRUE,ISNUMBER(1*MID(R11,ROW($1:$13),1)),0),COUNT(1*MID(R11,ROW($1:$13),1))),"غير محدد")} -> 1 | U11: يحتاج الى إعادة | V11: =الجدول1[[#This Row],[CO2]]/الجدول1[[#This Row],[CO]] -> 7.2872727 | W11: =الجدول1[[#This Row],[C2H2]]/الجدول1[[#This Row],[C2H4]] -> 0 | X11: =الجدول1[[#This Row],[C2H4]]/الجدول1[[#This Row],[C2H6]] -> 0.2 | Y11: =الجدول1[[#This Row],[CH4]]/الجدول1[[#This Row],[H2]] -> 0.020242915 | Z11: =IFERROR(DATEDIF(S11,TODAY(),"MD") & " ","0 ") -> 27
A12: أبو قرقاص 66 | B12: 2T | C12: 66 / 11 | D12: 45616 | E12: =IFERROR(DATEDIF(D12,TODAY(),"YM") & " m " & DATEDIF(D12,TODAY(),"MD") & " D "," ") -> 0 m 26 D | F12: 9942 | G12: 42195 | H12: =الجدول1[[#This Row],[O2]]/الجدول1[[#This Row],[N2]] -> 0.23562033 | I12: 126 | J12: 2595 | K12: 3 | L12: 4 | M12: 0 | N12: 1 | O12: 170 | P12: T3 | Q12: S3 | R12: R1 | S12: =IFERROR(IF(T12>=1,EDATE(D12,T12),"غير محدد"),"غير محدد") -> 45646 | T12: {=IFERROR(MID(R12,MATCH(TRUE,ISNUMBER(1*MID(R12,ROW($1:$13),1)),0),COUNT(1*MID(R12,ROW($1:$13),1))),"غير محدد")} -> 1 | U12: يحتاج الى إعادة | V12: =الجدول1[[#This Row],[CO2]]/الجدول1[[#This Row],[CO]] -> 15.264706 | W12: =الجدول1[[#This Row],[C2H2]]/الجدول1[[#This Row],[C2H4]] -> 0 | X12: =الجدول1[[#This Row],[C2H4]]/الجدول1[[#This Row],[C2H6]] -> 0.75 | Y12: =الجدول1[[#This Row],[CH4]]/الجدول1[[#This Row],[H2]] -> 0.0079365079 | Z12: =IFERROR(DATEDIF(S12,TODAY(),"MD") & " ","0 ") -> 26
A13: أبو قرقاص 66 | B13: 3T | C13: 66 / 11 | D13: 45412 | E13: =IFERROR(DATEDIF(D13,TODAY(),"YM") & " m " & DATEDIF(D13,TODAY(),"MD") & " D "," ") -> 7 m 16 D | F13: 25698 | G13: 99833 | H13: =الجدول1[[#This Row],[O2]]/الجدول1[[#This Row],[N2]] -> 0.25740987 | I13: 45 | J13: 1884 | K13: 2 | L13: 1 | M13: 0 | N13: 2 | O13: 141 | P13: - | Q13: S2 | R13: R1 | S13: =IFERROR(IF(T13>=1,EDATE(D13,T13),"غير محدد"),"غير محدد") -> 45442 | T13: {=IFERROR(MID(R13,MATCH(TRUE,ISNUMBER(1*MID(R13,ROW($1:$13),1)),0),COUNT(1*MID(R13,ROW($1:$13),1))),"غير محدد")} -> 1 | U13: يحتاج الى إعادة | V13: =الجدول1[[#This Row],[CO2]]/الجدول1[[#This Row],[CO]] -> 13.361702 | W13: =الجدول1[[#This Row],[C2H2]]/الجدول1[[#This Row],[C2H4]] -> 0 | X13: =الجدول1[[#This Row],[C2H4]]/الجدول1[[#This Row],[C2H6]] -> 2 | Y13: =الجدول1[[#This Row],[CH4]]/الجدول1[[#This Row],[H2]] -> 0.044444444 | Z13: =IFERROR(DATEDIF(S13,TODAY(),"MD") & " ","0 ") -> 16
A14: أبو قرقاص 66 | B14: 4T | C14: 66 / 11 | D14: 45372 | E14: =IFERROR(DATEDIF(D14,TODAY(),"YM") & " m " & DATEDIF(D14,TODAY(),"MD") & " D "," ") -> 8 m 25 D | F14: 5484 | G14: 74234 | H14: =الجدول1[[#This Row],[O2]]/الجدول1[[#This Row],[N2]] -> 0.073874505 | I14: 229 | J14: 4432 | K14: 106 | L14: 3 | M14: 0 | N14: 12 | O14: 732 | P14: T3 | Q14: S3 | R14: R1 | S14: =IFERROR(IF(T14>=1,EDATE(D14,T14),"غير محدد"),"غير محدد") -> 45403 | T14: {=IFERROR(MID(R14,MATCH(TRUE,ISNUMBER(1*MID(R14,ROW($1:$13),1)),0),COUNT(1*MID(R14,ROW($1:$13),1))),"غير محدد")} -> 1 | U14: تم | V14: =الجدول1[[#This Row],[CO2]]/الجدول1[[#This Row],[CO]] -> 6.0546448 | W14: =الجدول1[[#This Row],[C2H2]]/الجدول1[[#This Row],[C2H4]] -> 0 | X14: =الجدول1[[#This Row],[C2H4]]/الجدول1[[#This Row],[C2H6]] -> 35.333333 | Y14: =الجدول1[[#This Row],[CH4]]/الجدول1[[#This Row],[H2]] -> 0.052401747 | Z14: =IFERROR(DATEDIF(S14,TODAY(),"MD") & " ","0 ") -> 25
A15: أبو قرقاص 66 | B15: 4T | C15: 66 / 11 | D15: 45412 | E15: =IFERROR(DATEDIF(D15,TODAY(),"YM") & " m " & DATEDIF(D15,TODAY(),"MD") & " D "," ") -> 7 m 16 D | F15: 1409 | G15: 90786 | H15: =الجدول1[[#This Row],[O2]]/الجدول1[[#This Row],[N2]] -> 0.015520014 | I15: 161 | J15: 3091 | K15: 118 | L15: 95 | M15: 0 | N15: 100 | O15: 751 | P15: T3 | Q15: S3 | R15: R1 | S15: =IFERROR(IF(T15>=1,EDATE(D15,T15),"غير محدد"),"غير محدد") -> 45442 | T15: {=IFERROR(MID(R15,MATCH(TRUE,ISNUMBER(1*MID(R15,ROW($1:$13),1)),0),COUNT(1*MID(R15,ROW($1:$13),1))),"غير محدد")} -> 1 | U15: تم | V15: =الجدول1[[#This Row],[CO2]]/الجدول1[[#This Row],[CO]] -> 4.1158455 | W15: =الجدول1[[#This Row],[C2H2]]/الجدول1[[#This Row],[C2H4]] -> 0 | X15: =الجدول1[[#This Row],[C2H4]]/الجدول1[[#This Row],[C2H6]] -> 1.2421053 | Y15: =الجدول1[[#This Row],[CH4]]/الجدول1[[#This Row],[H2]] -> 0.62111801 | Z15: =IFERROR(DATEDIF(S15,TODAY(),"MD") & " ","0 ") -> 16
A16: أبو قرقاص 66 | B16: 4T | C16: 66 / 11 | D16: 45480 | E16: =IFERROR(DATEDIF(D16,TODAY(),"YM") & " m " & DATEDIF(D16,TODAY(),"MD") & " D "," ") -> 5 m 9 D | F16: 1588 | G16: 78319 | H16: =الجدول1[[#This Row],[O2]]/الجدول1[[#This Row],[N2]] -> 0.020276051 | I16: 159 | J16: 3979 | K16: 116 | L16: 167 | M16: 0 | N16: 5 | O16: 158 | P16: T3 | Q16: S3 | R16: I | S16: =IFERROR(IF(T16>=1,EDATE(D16,T16),"غير محدد"),"غير محدد") -> غير محدد | T16: {=IFERROR(MID(R16,MATCH(TRUE,ISNUMBER(1*MID(R16,ROW($1:$13),1)),0),COUNT(1*MID(R16,ROW($1:$13),1))),"غير محدد")} -> غير محدد | U16: تم | V16: =الجدول1[[#This Row],[CO2]]/الجدول1[[#This Row],[CO]] -> 25.183544 | W16: =الجدول1[[#This Row],[C2H2]]/الجدول1[[#This Row],[C2H4]] -> 0 | X16: =الجدول1[[#This Row],[C2H4]]/الجدول1[[#This Row],[C2H6]] -> 0.69461078 | Y16: =الجدول1[[#This Row],[CH4]]/الجدول1[[#This Row],[H2]] -> 0.031446541 | Z16: =IFERROR(DATEDIF(S16,TODAY(),"MD") & " ","0 ") -> 0
A17: أبو قرقاص 66 | B17: 4T | C17: 66 / 11 | D17: 45572 | E17: =IFERROR(DATEDIF(D17,TODAY(),"YM") & " m " & DATEDIF(D17,TODAY(),"MD") & " D "," ") -> 2 m 9 D | F17: 11291 | G17: 111266 | H17: =الجدول1[[#This Row],[O2]]/الجدول1[[#This Row],[N2]] -> 0.10147754 | I17: 360 | J17: 4324 | K17: 1 | L17: 17 | M17: 0 | N17: 4 | O17: 623 | P17: - | Q17: S3 | R17: R1 | S17: =IFERROR(IF(T17>=1,EDATE(D17,T17),"غير محدد"),"غير محدد") -> 45603 | T17: {=IFERROR(MID(R17,MATCH(TRUE,ISNUMBER(1*MID(R17,ROW($1:$13),1)),0),COUNT(1*MID(R17,ROW($1:$13),1))),"غير محدد")} -> 1 | U17: تم | V17: =الجدول1[[#This Row],[CO2]]/الجدول1[[#This Row],[CO]] -> 6.94061 | W17: =الجدول1[[#This Row],[C2H2]]/الجدول1[[#This Row],[C2H4]] -> 0 | X17: =الجدول1[[#This Row],[C2H4]]/الجدول1[[#This Row],[C2H6]] -> 0.058823529 | Y17: =الجدول1[[#This Row],[CH4]]/الجدول1[[#This Row],[H2]] -> 0.011111111 | Z17: =IFERROR(DATEDIF(S17,TODAY(),"MD") & " ","0 ") -> 9
A18: أبو قرقاص 66 | B18: 4T | C18: 66 / 11 | D18: 45574 | E18: =IFERROR(DATEDIF(D18,TODAY(),"YM") & " m " & DATEDIF(D18,TODAY(),"MD") & " D "," ") -> 2 m 7 D | F18: 25820 | G18: 227466 | H18: =الجدول1[[#This Row],[O2]]/الجدول1[[#This Row],[N2]] -> 0.11351147 | I18: 189 | J18: 5035 | K18: 195 | L18: 353 | M18: 0 | N18: 140 | O18: 906 | P18: T3 | Q18: S3 | R18: I | S18: =IFERROR(IF(T18>=1,EDATE(D18,T18),"غير محدد"),"غير محدد") -> غير محدد | T18: {=IFERROR(MID(R18,MATCH(TRUE,ISNUMBER(1*MID(R18,ROW($1:$13),1)),0),COUNT(1*MID(R18,ROW($1:$13),1))),"غير محدد")} -> غير محدد | U18: تم | V18: =الجدول1[[#This Row],[CO2]]/الجدول1[[#This Row],[CO]] -> 5.5573951 | W18: =الجدول1[[#This Row],[C2H2]]/الجدول1[[#This Row],[C2H4]] -> 0 | X18: =الجدول1[[#This Row],[C2H4]]/الجدول1[[#This Row],[C2H6]] -> 0.55240793 | Y18: =الجدول1[[#This Row],[CH4]]/الجدول1[[#This Row],[H2]] -> 0.74074074 | Z18: =IFERROR(DATEDIF(S18,TODAY(),"MD") & " ","0 ") -> 0
A19: أبو قرقاص 66 | B19: 4T | C19: 66 / 11 | D19: 45630 | E19: =IFERROR(DATEDIF(D19,TODAY(),"YM") & " m " & DATEDIF(D19,TODAY(),"MD") & " D "," ") -> 0 m 12 D | F19: 13072 | G19: 54140 | H19: =الجدول1[[#This Row],[O2]]/الجدول1[[#This Row],[N2]] -> 0.2414481 | I19: 49 | J19: 2178 | K19: 42 | L19: 180 | M19: 0 | N19: 56 | O19: 105 | P19: T2 | Q19: S3 | R19: R1 | S19: =IFERROR(IF(T19>=1,EDATE(D19,T19),"غير محدد"),"غير محدد") -> 45661 | T19: {=IFERROR(MID(R19,MATCH(TRUE,ISNUMBER(1*MID(R19,ROW($1:$13),1)),0),COUNT(1*MID(R19,ROW($1:$13),1))),"غير محدد")} -> 1 | U19: يحتاج الى إعادة | V19: =الجدول1[[#This Row],[CO2]]/الجدول1[[#This Row],[CO]] -> 20.742857 | W19: =الجدول1[[#This Row],[C2H2]]/الجدول1[[#This Row],[C2H4]] -> 0 | X19: =الجدول1[[#This Row],[C2H4]]/الجدول1[[#This Row],[C2H6]] -> 0.23333333 | Y19: =الجدول1[[#This Row],[CH4]]/الجدول1[[#This Row],[H2]] -> 1.1428571 | Z19: =IFERROR(DATEDIF(S19,TODAY(),"MD") & " ","0 ") -> 12
A20: ألجامعة بالمنيا | B20: 1T | C20: 33 /11 | D20: 45217 | E20: =IFERROR(DATEDIF(D20,TODAY(),"YM") & " m " & DATEDIF(D20,TODAY(),"MD") & " D "," ") -> 1 m 28 D | F20: 33460 | G20: 151524 | H20: =الجدول1[[#This Row],[O2]]/الجدول1[[#This Row],[N2]] -> 0.2208231 | I20: 61 | J20: 10427 | K20: 8 | L20: 4 | M20: 9 | N20: 2 | O20: 665 | P20: D2 | Q20: S3 | R20: R | S20: =IFERROR(IF(T20>=1,EDATE(D20,T20),"غير محدد"),"غير محدد") -> غير محدد | T20: {=IFERROR(MID(R20,MATCH(TRUE,ISNUMBER(1*MID(R20,ROW($1:$13),1)),0),COUNT(1*MID(R20,ROW($1:$13),1))),"غير محدد")} -> غير محدد | U20: تم | V20: =الجدول1[[#This Row],[CO2]]/الجدول1[[#This Row],[CO]] -> 15.679699 | W20: =الجدول1[[#This Row],[C2H2]]/الجدول1[[#This Row],[C2H4]] -> 1.125 | X20: =الجدول1[[#This Row],[C2H4]]/الجدول1[[#This Row],[C2H6]] -> 2 | Y20: =الجدول1[[#This Row],[CH4]]/الجدول1[[#This Row],[H2]] -> 0.032786885 | Z20: =IFERROR(DATEDIF(S20,TODAY(),"MD") & " ","0 ") -> 0
A21: ألجامعة بالمنيا | B21: 1T | C21: 33 /11 | D21: 45372 | E21: =IFERROR(DATEDIF(D21,TODAY(),"YM") & " m " & DATEDIF(D21,TODAY(),"MD") & " D "," ") -> 8 m 25 D | F21: 20627 | G21: 60462 | H21: =الجدول1[[#This Row],[O2]]/الجدول1[[#This Row],[N2]] -> 0.34115643 | I21: 36 | J21: 3787 | K21: 1 | L21: 2 | M21: 0 | N21: 1 | O21: 145 | P21: T3 | Q21: S3 | R21: R1 | S21: =IFERROR(IF(T21>=1,EDATE(D21,T21),"غير محدد"),"غير محدد") -> 45403 | T21: {=IFERROR(MID(R21,MATCH(TRUE,ISNUMBER(1*MID(R21,ROW($1:$13),1)),0),COUNT(1*MID(R21,ROW($1:$13),1))),"غير محدد")} -> 1 | U21: يحتاج الى إعادة | V21: =الجدول1[[#This Row],[CO2]]/الجدول1[[#This Row],[CO]] -> 26.117241 | W21: =الجدول1[[#This Row],[C2H2]]/الجدول1[[#This Row],[C2H4]] -> 0 | X21: =الجدول1[[#This Row],[C2H4]]/الجدول1[[#This Row],[C2H6]] -> 0.5 | Y21: =الجدول1[[#This Row],[CH4]]/الجدول1[[#This Row],[H2]] -> 0.027777778 | Z21: =IFERROR(DATEDIF(S21,TODAY(),"MD") & " ","0 ") -> 25
... A36: بني خالد | B36: 2T | C36: 33 /11 | D36: 45372 | E36: =IFERROR(DATEDIF(D36,TODAY(),"YM") & " m " & DATEDIF(D36,TODAY(),"MD") & " D "," ") -> 8 m 25 D | F36: 20672 | G36: 80642 | H36: =الجدول1[[#This Row],[O2]]/الجدول1[[#This Row],[N2]] -> 0.25634285 | I36: 20 | J36: 4664 | K36: 1 | L36: 2 | M36: 0 | N36: 1 | O36: 216 | P36: - | Q36: S3 | R36: R6 | S36: =IFERROR(IF(T36>=1,EDATE(D36,T36),"غير محدد"),"غير محدد") -> 45556 | T36: {=IFERROR(MID(R36,MATCH(TRUE,ISNUMBER(1*MID(R36,ROW($1:$13),1)),0),COUNT(1*MID(R36,ROW($1:$13),1))),"غير محدد")} -> 6 | U36: يحتاج الى إعادة | V36: =الجدول1[[#This Row],[CO2]]/الجدول1[[#This Row],[CO]] -> 21.592593 | W36: =الجدول1[[#This Row],[C2H2]]/الجدول1[[#This Row],[C2H4]] -> 0 | X36: =الجدول1[[#This Row],[C2H4]]/الجدول1[[#This Row],[C2H6]] -> 0.5 | Y36: =الجدول1[[#This Row],[CH4]]/الجدول1[[#This Row],[H2]] -> 0.05 | Z36: =IFERROR(DATEDIF(S36,TODAY(),"MD") & " ","0 ") -> 25
A37: دير سمالوط | B37: 1T | C37: 66 / 11 | D37: 44901 | E37: =IFERROR(DATEDIF(D37,TODAY(),"YM") & " m " & DATEDIF(D37,TODAY(),"MD") & " D "," ") -> 0 m 10 D | F37: 11661 | G37: 75456 | H37: =الجدول1[[#This Row],[O2]]/الجدول1[[#This Row],[N2]] -> 0.15454039 | I37: 103 | J37: 1535 | K37: 143 | L37: 7 | M37: 0 | N37: 6 | O37: 577 | P37: T3 | Q37: 2 | R37: R | S37: =IFERROR(IF(T37>=1,EDATE(D37,T37),"غير محدد"),"غير محدد") -> غير محدد | T37: {=IFERROR(MID(R37,MATCH(TRUE,ISNUMBER(1*MID(R37,ROW($1:$13),1)),0),COUNT(1*MID(R37,ROW($1:$13),1))),"غير محدد")} -> غير محدد | U37: تم | V37: =الجدول1[[#This Row],[CO2]]/الجدول1[[#This Row],[CO]] -> 2.660312 | W37: =الجدول1[[#This Row],[C2H2]]/الجدول1[[#This Row],[C2H4]] -> 0 | X37: =الجدول1[[#This Row],[C2H4]]/الجدول1[[#This Row],[C2H6]] -> 20.428571 | Y37: =الجدول1[[#This Row],[CH4]]/الجدول1[[#This Row],[H2]] -> 0.058252427 | Z37: =IFERROR(DATEDIF(S37,TODAY(),"MD") & " ","0 ") -> 0
A38: دير سمالوط | B38: 1T | C38: 66 / 11 | D38: 44949 | E38: =IFERROR(DATEDIF(D38,TODAY(),"YM") & " m " & DATEDIF(D38,TODAY(),"MD") & " D "," ") -> 10 m 23 D | F38: 16757 | G38: 47755 | H38: =الجدول1[[#This Row],[O2]]/الجدول1[[#This Row],[N2]] -> 0.35089519 | I38: 103 | J38: 719 | K38: 4 | L38: 3 | M38: 1 | N38: 1 | O38: 235 | P38: N | Q38: 1 | R38: S | S38: =IFERROR(IF(T38>=1,EDATE(D38,T38),"غير محدد"),"غير محدد") -> غير محدد | T38: {=IFERROR(MID(R38,MATCH(TRUE,ISNUMBER(1*MID(R38,ROW($1:$13),1)),0),COUNT(1*MID(R38,ROW($1:$13),1))),"غير محدد")} -> غير محدد | U38: تم | V38: =الجدول1[[#This Row],[CO2]]/الجدول1[[#This Row],[CO]] -> 3.0595745 | W38: =الجدول1[[#This Row],[C2H2]]/الجدول1[[#This Row],[C2H4]] -> 0.25 | X38: =الجدول1[[#This Row],[C2H4]]/الجدول1[[#This Row],[C2H6]] -> 1.3333333 | Y38: =الجدول1[[#This Row],[CH4]]/الجدول1[[#This Row],[H2]] -> 0.0097087379 | Z38: =IFERROR(DATEDIF(S38,TODAY(),"MD") & " ","0 ") -> 0
A39: دير سمالوط | B39: 1T | C39: 66 / 11 | D39: 45266 | E39: =IFERROR(DATEDIF(D39,TODAY(),"YM") & " m " & DATEDIF(D39,TODAY(),"MD") & " D "," ") -> 0 m 10 D | F39: 8556 | G39: 75883 | H39: =الجدول1[[#This Row],[O2]]/الجدول1[[#This Row],[N2]] -> 0.11275253 | I39: 121 | J39: 3715 | K39: 2 | L39: 15 | M39: 0 | N39: 1 | O39: 403 | P39: T3 | Q39: S3 | R39: R | S39: =IFERROR(IF(T39>=1,EDATE(D39,T39),"غير محدد"),"غير محدد") -> غير محدد | T39: {=IFERROR(MID(R39,MATCH(TRUE,ISNUMBER(1*MID(R39,ROW($1:$13),1)),0),COUNT(1*MID(R39,ROW($1:$13),1))),"غير محدد")} -> غير محدد | U39: يحتاج الى إعادة | V39: =الجدول1[[#This Row],[CO2]]/الجدول1[[#This Row],[CO]] -> 9.2183623 | W39: =الجدول1[[#This Row],[C2H2]]/الجدول1[[#This Row],[C2H4]] -> 0 | X39: =الجدول1[[#This Row],[C2H4]]/الجدول1[[#This Row],[C2H6]] -> 0.13333333 | Y39: =الجدول1[[#This Row],[CH4]]/الجدول1[[#This Row],[H2]] -> 0.0082644628 | Z39: =IFERROR(DATEDIF(S39,TODAY(),"MD") & " ","0 ") -> 0
A40: دير سمالوط | B40: 2T | C40: 66 / 11 | D40: 45587 | E40: =IFERROR(DATEDIF(D40,TODAY(),"YM") & " m " & DATEDIF(D40,TODAY(),"MD") & " D "," ") -> 1 m 24 D | F40: 8249 | G40: 72378 | H40: =الجدول1[[#This Row],[O2]]/الجدول1[[#This Row],[N2]] -> 0.1139711 | I40: 85 | J40: 3970 | K40: 16 | L40: 38 | M40: 0 | N40: 2 | O40: 336 | P40: T3 | Q40: S3 | R40: R1 | S40: =IFERROR(IF(T40>=1,EDATE(D40,T40),"غير محدد"),"غير محدد") -> 45618 | T40: {=IFERROR(MID(R40,MATCH(TRUE,ISNUMBER(1*MID(R40,ROW($1:$13),1)),0),COUNT(1*MID(R40,ROW($1:$13),1))),"غير محدد")} -> 1 | U40: يحتاج الى إعادة | V40: =الجدول1[[#This Row],[CO2]]/الجدول1[[#This Row],[CO]] -> 11.815476 | W40: =الجدول1[[#This Row],[C2H2]]/الجدول1[[#This Row],[C2H4]] -> 0 | X40: =الجدول1[[#This Row],[C2H4]]/الجدول1[[#This Row],[C2H6]] -> 0.42105263 | Y40: =الجدول1[[#This Row],[CH4]]/الجدول1[[#This Row],[H2]] -> 0.023529412 | Z40: =IFERROR(DATEDIF(S40,TODAY(),"MD") & " ","0 ") -> 24
A41: دير سمالوط | B41: 4T | C41: 66 / 11 | D41: 45266 | E41: =IFERROR(DATEDIF(D41,TODAY(),"YM") & " m " & DATEDIF(D41,TODAY(),"MD") & " D "," ") -> 0 m 10 D | F41: 29081 | G41: 82175 | H41: =الجدول1[[#This Row],[O2]]/الجدول1[[#This Row],[N2]] -> 0.35389109 | I41: 388 | J41: 1413 | K41: 3 | L41: 9 | M41: 0 | N41: 1 | O41: 201 | P41: T3 | Q41: S3 | R41: R | S41: =IFERROR(IF(T41>=1,EDATE(D41,T41),"غير محدد"),"غير محدد") -> غير محدد | T41: {=IFERROR(MID(R41,MATCH(TRUE,ISNUMBER(1*MID(R41,ROW($1:$13),1)),0),COUNT(1*MID(R41,ROW($1:$13),1))),"غير محدد")} -> غير محدد | U41: تم | V41: =الجدول1[[#This Row],[CO2]]/الجدول1[[#This Row],[CO]] -> 7.0298507 | W41: =الجدول1[[#This Row],[C2H2]]/الجدول1[[#This Row],[C2H4]] -> 0 | X41: =الجدول1[[#This Row],[C2H4]]/الجدول1[[#This Row],[C2H6]] -> 0.33333333 | Y41: =الجدول1[[#This Row],[CH4]]/الجدول1[[#This Row],[H2]] -> 0.0025773196 | Z41: =IFERROR(DATEDIF(S41,TODAY(),"MD") & " ","0 ") -> 0
A42: دير سمالوط | B42: 4T | C42: 66 / 11 | D42: 45587 | E42: =IFERROR(DATEDIF(D42,TODAY(),"YM") & " m " & DATEDIF(D42,TODAY(),"MD") & " D "," ") -> 1 m 24 D | F42: 19884 | G42: 73512 | H42: =الجدول1[[#This Row],[O2]]/الجدول1[[#This Row],[N2]] -> 0.27048645 | I42: 530 | J42: 2279 | K42: 6 | L42: 20 | M42: 0 | N42: 2 | O42: 197 | P42: T3 | Q42: S3 | R42: R1 | S42: =IFERROR(IF(T42>=1,EDATE(D42,T42),"غير محدد"),"غير محدد") -> 45618 | T42: {=IFERROR(MID(R42,MATCH(TRUE,ISNUMBER(1*MID(R42,ROW($1:$13),1)),0),COUNT(1*MID(R42,ROW($1:$13),1))),"غير محدد")} -> 1 | U42: تم | V42: =الجدول1[[#This Row],[CO2]]/الجدول1[[#This Row],[CO]] -> 11.568528 | W42: =الجدول1[[#This Row],[C2H2]]/الجدول1[[#This Row],[C2H4]] -> 0 | X42: =الجدول1[[#This Row],[C2H4]]/الجدول1[[#This Row],[C2H6]] -> 0.3 | Y42: =الجدول1[[#This Row],[CH4]]/الجدول1[[#This Row],[H2]] -> 0.0037735849 | Z42: =IFERROR(DATEDIF(S42,TODAY(),"MD") & " ","0 ") -> 24
A43: دير سمالوط | B43: 4T | C43: 66 / 11 | D43: 45726 | E43: =IFERROR(DATEDIF(D43,TODAY(),"YM") & " m " & DATEDIF(D43,TODAY(),"MD") & " D "," ") -> 9 m 6 D | F43: 31507 | G43: 74813 | H43: =الجدول1[[#This Row],[O2]]/الجدول1[[#This Row],[N2]] -> 0.42114338 | I43: 429 | J43: 2003 | K43: 4 | L43: 15 | M43: 0 | N43: 1 | O43: 91 | P43: T3 | Q43: S3 | R43: R1 | S43: =IFERROR(IF(T43>=1,EDATE(D43,T43),"غير محدد"),"غير محدد") -> 45757 | T43: {=IFERROR(MID(R43,MATCH(TRUE,ISNUMBER(1*MID(R43,ROW($1:$13),1)),0),COUNT(1*MID(R43,ROW($1:$13),1))),"غير محدد")} -> 1 | U43: تم | V43: =الجدول1[[#This Row],[CO2]]/الجدول1[[#This Row],[CO]] -> 22.010989 | W43: =الجدول1[[#This Row],[C2H2]]/الجدول1[[#This Row],[C2H4]] -> 0 | X43: =الجدول1[[#This Row],[C2H4]]/الجدول1[[#This Row],[C2H6]] -> 0.26666667 | Y43: =الجدول1[[#This Row],[CH4]]/الجدول1[[#This Row],[H2]] -> 0.0023310023 | Z43: =IFERROR(DATEDIF(S43,TODAY(),"MD") & " ","0 ") -> 6
A44: دير سمالوط | B44: 4T | C44: 66 / 11 | D44: 45797 | E44: =IFERROR(DATEDIF(D44,TODAY(),"YM") & " m " & DATEDIF(D44,TODAY(),"MD") & " D "," ") -> 6 m 26 D | F44: 29792 | G44: 72230 | H44: =الجدول1[[#This Row],[O2]]/الجدول1[[#This Row],[N2]] -> 0.4124602 | I44: 785 | J44: 2146 | K44: 5 | L44: 15 | M44: 0 | N44: 17 | O44: 154 | P44: T2 | Q44: S3 | R44: R1 | S44: =IFERROR(IF(T44>=1,EDATE(D44,T44),"غير محدد"),"غير محدد") -> 45828 | T44: {=IFERROR(MID(R44,MATCH(TRUE,ISNUMBER(1*MID(R44,ROW($1:$13),1)),0),COUNT(1*MID(R44,ROW($1:$13),1))),"غير محدد")} -> 1 | U44: تم | V44: =الجدول1[[#This Row],[CO2]]/الجدول1[[#This Row],[CO]] -> 13.935065 | W44: =الجدول1[[#This Row],[C2H2]]/الجدول1[[#This Row],[C2H4]] -> 0 | X44: =الجدول1[[#This Row],[C2H4]]/الجدول1[[#This Row],[C2H6]] -> 0.33333333 | Y44: =الجدول1[[#This Row],[CH4]]/الجدول1[[#This Row],[H2]] -> 0.021656051 | Z44: =IFERROR(DATEDIF(S44,TODAY(),"MD") & " ","0 ") -> 26
A45: دير سمالوط | B45: 4T | C45: 66 / 11 | D45: 45890 | E45: =IFERROR(DATEDIF(D45,TODAY(),"YM") & " m " & DATEDIF(D45,TODAY(),"MD") & " D "," ") -> 3 m 25 D | F45: 4081 | G45: 115197 | H45: =الجدول1[[#This Row],[O2]]/الجدول1[[#This Row],[N2]] -> 0.03542627 | I45: 121 | J45: 7994 | K45: 8 | L45: 111 | M45: 0 | N45: 10 | O45: 441 | P45: T2 | Q45: S3 | R45: R3 | S45: =IFERROR(IF(T45>=1,EDATE(D45,T45),"غير محدد"),"غير محدد") -> 45982 | T45: {=IFERROR(MID(R45,MATCH(TRUE,ISNUMBER(1*MID(R45,ROW($1:$13),1)),0),COUNT(1*MID(R45,ROW($1:$13),1))),"غير محدد")} -> 3 | U45: يحتاج الى إعادة | V45: =الجدول1[[#This Row],[CO2]]/الجدول1[[#This Row],[CO]] -> 18.126984 | W45: =الجدول1[[#This Row],[C2H2]]/الجدول1[[#This Row],[C2H4]] -> 0 | X45: =الجدول1[[#This Row],[C2H4]]/الجدول1[[#This Row],[C2H6]] -> 0.072072072 | Y45: =الجدول1[[#This Row],[CH4]]/الجدول1[[#This Row],[H2]] -> 0.082644628 | Z45: =IFERROR(DATEDIF(S45,TODAY(),"MD") & " ","0 ") -> 25
A46: دير مواس | B46: 1T | C46: 66 / 11 | D46: 45208 | E46: =IFERROR(DATEDIF(D46,TODAY(),"YM") & " m " & DATEDIF(D46,TODAY(),"MD") & " D "," ") -> 2 m 7 D | F46: 13374 | G46: 134456 | H46: =الجدول1[[#This Row],[O2]]/الجدول1[[#This Row],[N2]] -> 0.099467484 | I46: 39 | J46: 5552 | K46: 1 | L46: 2 | M46: 0 | N46: 2 | O46: 397 | P46: T2 | Q46: S3 | R46: R | S46: =IFERROR(IF(T46>=1,EDATE(D46,T46),"غير محدد"),"غير محدد") -> غير محدد | T46: {=IFERROR(MID(R46,MATCH(TRUE,ISNUMBER(1*MID(R46,ROW($1:$13),1)),0),COUNT(1*MID(R46,ROW($1:$13),1))),"غير محدد")} -> غير محدد | U46: يحتاج الى إعادة | V46: =الجدول1[[#This Row],[CO2]]/الجدول1[[#This Row],[CO]] -> 13.984887 | W46: =الجدول1[[#This Row],[C2H2]]/الجدول1[[#This Row],[C2H4]] -> 0 | X46: =الجدول1[[#This Row],[C2H4]]/الجدول1[[#This Row],[C2H6]] -> 0.5 | Y46: =الجدول1[[#This Row],[CH4]]/الجدول1[[#This Row],[H2]] -> 0.051282051 | Z46: =IFERROR(DATEDIF(S46,TODAY(),"MD") & " ","0 ") -> 0
A47: دير مواس | B47: 2T | C47: 66 / 11 | D47: 45208 | E47: =IFERROR(DATEDIF(D47,TODAY(),"YM") & " m " & DATEDIF(D47,TODAY(),"MD") & " D "," ") -> 2 m 7 D | F47: 9238 | G47: 150492 | H47: =الجدول1[[#This Row],[O2]]/الجدول1[[#This Row],[N2]] -> 0.061385323 | I47: 25 | J47: 4093 | K47: 2 | L47: 3 | M47: 0 | N47: 2 | O47: 435 | P47: T3 | Q47: S3 | R47: R | S47: =IFERROR(IF(T47>=1,EDATE(D47,T47),"غير محدد"),"غير محدد") -> غير محدد | T47: {=IFERROR(MID(R47,MATCH(TRUE,ISNUMBER(1*MID(R47,ROW($1:$13),1)),0),COUNT(1*MID(R47,ROW($1:$13),1))),"غير محدد")} -> غير محدد | U47: يحتاج الى إعادة | V47: =الجدول1[[#This Row],[CO2]]/الجدول1[[#This Row],[CO]] -> 9.4091954 | W47: =الجدول1[[#This Row],[C2H2]]/الجدول1[[#This Row],[C2H4]] -> 0 | X47: =الجدول1[[#This Row],[C2H4]]/الجدول1[[#This Row],[C2H6]] -> 0.66666667 | Y47: =الجدول1[[#This Row],[CH4]]/الجدول1[[#This Row],[H2]] -> 0.08 | Z47: =IFERROR(DATEDIF(S47,TODAY(),"MD") & " ","0 ") -> 0
A48: دير مواس | B48: 3T | C48: 66 / 11 | D48: 45208 | E48: 11 m 3 D | F48: 53322 | G48: 149161 | H48: =الجدول1[[#This Row],[O2]]/الجدول1[[#This Row],[N2]] -> 0.3574795 | I48: 26 | J48: 4133 | K48: 2 | L48: 3 | M48: 0 | N48: 1 | O48: 263 | P48: T3 | Q48: S3 | R48: R | S48: =IFERROR(IF(T48>=1,EDATE(D48,T48),"غير محدد"),"غير محدد") -> غير محدد | T48: {=IFERROR(MID(R48,MATCH(TRUE,ISNUMBER(1*MID(R48,ROW($1:$13),1)),0),COUNT(1*MID(R48,ROW($1:$13),1))),"غير محدد")} -> غير محدد | U48: يحتاج الى إعادة | V48: =الجدول1[[#This Row],[CO2]]/الجدول1[[#This Row],[CO]] -> 15.714829 | W48: =الجدول1[[#This Row],[C2H2]]/الجدول1[[#This Row],[C2H4]] -> 0 | X48: =الجدول1[[#This Row],[C2H4]]/الجدول1[[#This Row],[C2H6]] -> 0.66666667 | Y48: =الجدول1[[#This Row],[CH4]]/الجدول1[[#This Row],[H2]] -> 0.038461538 | Z48: =IFERROR(DATEDIF(S48,TODAY(),"MD") & " ","0 ") -> 0
A49: سمالوط 500 | B49: 1T PH A | C49: 500 / 132 | D49: 45230 | E49: =IFERROR(DATEDIF(D49,TODAY(),"YM") & " m " & DATEDIF(D49,TODAY(),"MD") & " D "," ") -> 1 m 15 D | F49: 2218 | G49: 100765 | H49: =الجدول1[[#This Row],[O2]]/الجدول1[[#This Row],[N2]] -> 0.022011611 | I49: 35 | J49: 7862 | K49: 3 | L49: 6 | M49: 0 | N49: 8 | O49: 1304 | P49: T2 | Q49: S3 | R49: R | S49: =IFERROR(IF(T49>=1,EDATE(D49,T49),"غير محدد"),"غير محدد") -> غير محدد | T49: {=IFERROR(MID(R49,MATCH(TRUE,ISNUMBER(1*MID(R49,ROW($1:$13),1)),0),COUNT(1*MID(R49,ROW($1:$13),1))),"غير محدد")} -> غير محدد | U49: يحتاج الى إعادة | V49: =الجدول1[[#This Row],[CO2]]/الجدول1[[#This Row],[CO]] -> 6.0291411 | W49: =الجدول1[[#This Row],[C2H2]]/الجدول1[[#This Row],[C2H4]] -> 0 | X49: =الجدول1[[#This Row],[C2H4]]/الجدول1[[#This Row],[C2H6]] -> 0.5 | Y49: =الجدول1[[#This Row],[CH4]]/الجدول1[[#This Row],[H2]] -> 0.22857143 | Z49: =IFERROR(DATEDIF(S49,TODAY(),"MD") & " ","0 ") -> 0
